2024-09-22 13:21:24,376 ERROR scheduler Exception in Enqueue Events for Site maigctable
Traceback (most recent call last):
  File "/home/magic/frappe-bench/apps/frappe/frappe/utils/scheduler.py", line 75, in enqueue_events_for_site
    if is_scheduler_inactive():
  File "/home/magic/frappe-bench/apps/frappe/frappe/utils/scheduler.py", line 117, in is_scheduler_inactive
    if is_scheduler_disabled(verbose=verbose):
  File "/home/magic/frappe-bench/apps/frappe/frappe/utils/scheduler.py", line 130, in is_scheduler_disabled
    frappe.db.get_single_value("System Settings", "enable_scheduler")
  File "/home/magic/frappe-bench/apps/frappe/frappe/database/database.py", line 834, in get_single_value
    ).run()
  File "/home/magic/frappe-bench/apps/frappe/frappe/query_builder/utils.py", line 87, in execute_query
    result = frappe.db.sql(query, params, *args, **kwargs)  # nosemgrep
  File "/home/magic/frappe-bench/apps/frappe/frappe/database/database.py", line 204, in sql
    self.connect()
  File "/home/magic/frappe-bench/apps/frappe/frappe/database/database.py", line 109, in connect
    self._conn: "MariadbConnection" | "PostgresConnection" = self.get_connection()
  File "/home/magic/frappe-bench/apps/frappe/frappe/database/mariadb/database.py", line 107, in get_connection
    conn = self._get_connection()
  File "/home/magic/frappe-bench/apps/frappe/frappe/database/mariadb/database.py", line 113, in _get_connection
    return self.create_connection()
  File "/home/magic/frappe-bench/apps/frappe/frappe/database/mariadb/database.py", line 116, in create_connection
    return pymysql.connect(**self.get_connection_settings())
  File "/home/magic/frappe-bench/env/lib/python3.10/site-packages/pymysql/connections.py", line 361, in __init__
    self.connect()
  File "/home/magic/frappe-bench/env/lib/python3.10/site-packages/pymysql/connections.py", line 669, in connect
    self._request_authentication()
  File "/home/magic/frappe-bench/env/lib/python3.10/site-packages/pymysql/connections.py", line 957, in _request_authentication
    auth_packet = self._read_packet()
  File "/home/magic/frappe-bench/env/lib/python3.10/site-packages/pymysql/connections.py", line 775, in _read_packet
    packet.raise_for_error()
  File "/home/magic/frappe-bench/env/lib/python3.10/site-packages/pymysql/protocol.py", line 219, in raise_for_error
    err.raise_mysql_exception(self._data)
  File "/home/magic/frappe-bench/env/lib/python3.10/site-packages/pymysql/err.py", line 150, in raise_mysql_exception
    raise errorclass(errno, errval)
pymysql.err.OperationalError: (1049, "Unknown database '_7c4e36808ec69197'")
2024-09-22 13:22:24,494 ERROR scheduler Exception in Enqueue Events for Site maigctable
Traceback (most recent call last):
  File "/home/magic/frappe-bench/apps/frappe/frappe/utils/scheduler.py", line 75, in enqueue_events_for_site
    if is_scheduler_inactive():
  File "/home/magic/frappe-bench/apps/frappe/frappe/utils/scheduler.py", line 117, in is_scheduler_inactive
    if is_scheduler_disabled(verbose=verbose):
  File "/home/magic/frappe-bench/apps/frappe/frappe/utils/scheduler.py", line 130, in is_scheduler_disabled
    frappe.db.get_single_value("System Settings", "enable_scheduler")
  File "/home/magic/frappe-bench/apps/frappe/frappe/database/database.py", line 834, in get_single_value
    ).run()
  File "/home/magic/frappe-bench/apps/frappe/frappe/query_builder/utils.py", line 87, in execute_query
    result = frappe.db.sql(query, params, *args, **kwargs)  # nosemgrep
  File "/home/magic/frappe-bench/apps/frappe/frappe/database/database.py", line 204, in sql
    self.connect()
  File "/home/magic/frappe-bench/apps/frappe/frappe/database/database.py", line 109, in connect
    self._conn: "MariadbConnection" | "PostgresConnection" = self.get_connection()
  File "/home/magic/frappe-bench/apps/frappe/frappe/database/mariadb/database.py", line 107, in get_connection
    conn = self._get_connection()
  File "/home/magic/frappe-bench/apps/frappe/frappe/database/mariadb/database.py", line 113, in _get_connection
    return self.create_connection()
  File "/home/magic/frappe-bench/apps/frappe/frappe/database/mariadb/database.py", line 116, in create_connection
    return pymysql.connect(**self.get_connection_settings())
  File "/home/magic/frappe-bench/env/lib/python3.10/site-packages/pymysql/connections.py", line 361, in __init__
    self.connect()
  File "/home/magic/frappe-bench/env/lib/python3.10/site-packages/pymysql/connections.py", line 669, in connect
    self._request_authentication()
  File "/home/magic/frappe-bench/env/lib/python3.10/site-packages/pymysql/connections.py", line 957, in _request_authentication
    auth_packet = self._read_packet()
  File "/home/magic/frappe-bench/env/lib/python3.10/site-packages/pymysql/connections.py", line 775, in _read_packet
    packet.raise_for_error()
  File "/home/magic/frappe-bench/env/lib/python3.10/site-packages/pymysql/protocol.py", line 219, in raise_for_error
    err.raise_mysql_exception(self._data)
  File "/home/magic/frappe-bench/env/lib/python3.10/site-packages/pymysql/err.py", line 150, in raise_mysql_exception
    raise errorclass(errno, errval)
pymysql.err.OperationalError: (1049, "Unknown database '_7c4e36808ec69197'")
2024-09-22 13:23:24,600 ERROR scheduler Exception in Enqueue Events for Site maigctable
Traceback (most recent call last):
  File "/home/magic/frappe-bench/apps/frappe/frappe/utils/scheduler.py", line 75, in enqueue_events_for_site
    if is_scheduler_inactive():
  File "/home/magic/frappe-bench/apps/frappe/frappe/utils/scheduler.py", line 117, in is_scheduler_inactive
    if is_scheduler_disabled(verbose=verbose):
  File "/home/magic/frappe-bench/apps/frappe/frappe/utils/scheduler.py", line 130, in is_scheduler_disabled
    frappe.db.get_single_value("System Settings", "enable_scheduler")
  File "/home/magic/frappe-bench/apps/frappe/frappe/database/database.py", line 834, in get_single_value
    ).run()
  File "/home/magic/frappe-bench/apps/frappe/frappe/query_builder/utils.py", line 87, in execute_query
    result = frappe.db.sql(query, params, *args, **kwargs)  # nosemgrep
  File "/home/magic/frappe-bench/apps/frappe/frappe/database/database.py", line 204, in sql
    self.connect()
  File "/home/magic/frappe-bench/apps/frappe/frappe/database/database.py", line 109, in connect
    self._conn: "MariadbConnection" | "PostgresConnection" = self.get_connection()
  File "/home/magic/frappe-bench/apps/frappe/frappe/database/mariadb/database.py", line 107, in get_connection
    conn = self._get_connection()
  File "/home/magic/frappe-bench/apps/frappe/frappe/database/mariadb/database.py", line 113, in _get_connection
    return self.create_connection()
  File "/home/magic/frappe-bench/apps/frappe/frappe/database/mariadb/database.py", line 116, in create_connection
    return pymysql.connect(**self.get_connection_settings())
  File "/home/magic/frappe-bench/env/lib/python3.10/site-packages/pymysql/connections.py", line 361, in __init__
    self.connect()
  File "/home/magic/frappe-bench/env/lib/python3.10/site-packages/pymysql/connections.py", line 669, in connect
    self._request_authentication()
  File "/home/magic/frappe-bench/env/lib/python3.10/site-packages/pymysql/connections.py", line 957, in _request_authentication
    auth_packet = self._read_packet()
  File "/home/magic/frappe-bench/env/lib/python3.10/site-packages/pymysql/connections.py", line 775, in _read_packet
    packet.raise_for_error()
  File "/home/magic/frappe-bench/env/lib/python3.10/site-packages/pymysql/protocol.py", line 219, in raise_for_error
    err.raise_mysql_exception(self._data)
  File "/home/magic/frappe-bench/env/lib/python3.10/site-packages/pymysql/err.py", line 150, in raise_mysql_exception
    raise errorclass(errno, errval)
pymysql.err.OperationalError: (1049, "Unknown database '_7c4e36808ec69197'")
2024-09-22 13:24:24,724 ERROR scheduler Exception in Enqueue Events for Site maigctable
Traceback (most recent call last):
  File "/home/magic/frappe-bench/apps/frappe/frappe/utils/scheduler.py", line 75, in enqueue_events_for_site
    if is_scheduler_inactive():
  File "/home/magic/frappe-bench/apps/frappe/frappe/utils/scheduler.py", line 117, in is_scheduler_inactive
    if is_scheduler_disabled(verbose=verbose):
  File "/home/magic/frappe-bench/apps/frappe/frappe/utils/scheduler.py", line 130, in is_scheduler_disabled
    frappe.db.get_single_value("System Settings", "enable_scheduler")
  File "/home/magic/frappe-bench/apps/frappe/frappe/database/database.py", line 834, in get_single_value
    ).run()
  File "/home/magic/frappe-bench/apps/frappe/frappe/query_builder/utils.py", line 87, in execute_query
    result = frappe.db.sql(query, params, *args, **kwargs)  # nosemgrep
  File "/home/magic/frappe-bench/apps/frappe/frappe/database/database.py", line 204, in sql
    self.connect()
  File "/home/magic/frappe-bench/apps/frappe/frappe/database/database.py", line 109, in connect
    self._conn: "MariadbConnection" | "PostgresConnection" = self.get_connection()
  File "/home/magic/frappe-bench/apps/frappe/frappe/database/mariadb/database.py", line 107, in get_connection
    conn = self._get_connection()
  File "/home/magic/frappe-bench/apps/frappe/frappe/database/mariadb/database.py", line 113, in _get_connection
    return self.create_connection()
  File "/home/magic/frappe-bench/apps/frappe/frappe/database/mariadb/database.py", line 116, in create_connection
    return pymysql.connect(**self.get_connection_settings())
  File "/home/magic/frappe-bench/env/lib/python3.10/site-packages/pymysql/connections.py", line 361, in __init__
    self.connect()
  File "/home/magic/frappe-bench/env/lib/python3.10/site-packages/pymysql/connections.py", line 669, in connect
    self._request_authentication()
  File "/home/magic/frappe-bench/env/lib/python3.10/site-packages/pymysql/connections.py", line 957, in _request_authentication
    auth_packet = self._read_packet()
  File "/home/magic/frappe-bench/env/lib/python3.10/site-packages/pymysql/connections.py", line 775, in _read_packet
    packet.raise_for_error()
  File "/home/magic/frappe-bench/env/lib/python3.10/site-packages/pymysql/protocol.py", line 219, in raise_for_error
    err.raise_mysql_exception(self._data)
  File "/home/magic/frappe-bench/env/lib/python3.10/site-packages/pymysql/err.py", line 150, in raise_mysql_exception
    raise errorclass(errno, errval)
pymysql.err.OperationalError: (1049, "Unknown database '_7c4e36808ec69197'")
2024-09-22 13:25:24,825 ERROR scheduler Exception in Enqueue Events for Site maigctable
Traceback (most recent call last):
  File "/home/magic/frappe-bench/apps/frappe/frappe/utils/scheduler.py", line 75, in enqueue_events_for_site
    if is_scheduler_inactive():
  File "/home/magic/frappe-bench/apps/frappe/frappe/utils/scheduler.py", line 117, in is_scheduler_inactive
    if is_scheduler_disabled(verbose=verbose):
  File "/home/magic/frappe-bench/apps/frappe/frappe/utils/scheduler.py", line 130, in is_scheduler_disabled
    frappe.db.get_single_value("System Settings", "enable_scheduler")
  File "/home/magic/frappe-bench/apps/frappe/frappe/database/database.py", line 834, in get_single_value
    ).run()
  File "/home/magic/frappe-bench/apps/frappe/frappe/query_builder/utils.py", line 87, in execute_query
    result = frappe.db.sql(query, params, *args, **kwargs)  # nosemgrep
  File "/home/magic/frappe-bench/apps/frappe/frappe/database/database.py", line 204, in sql
    self.connect()
  File "/home/magic/frappe-bench/apps/frappe/frappe/database/database.py", line 109, in connect
    self._conn: "MariadbConnection" | "PostgresConnection" = self.get_connection()
  File "/home/magic/frappe-bench/apps/frappe/frappe/database/mariadb/database.py", line 107, in get_connection
    conn = self._get_connection()
  File "/home/magic/frappe-bench/apps/frappe/frappe/database/mariadb/database.py", line 113, in _get_connection
    return self.create_connection()
  File "/home/magic/frappe-bench/apps/frappe/frappe/database/mariadb/database.py", line 116, in create_connection
    return pymysql.connect(**self.get_connection_settings())
  File "/home/magic/frappe-bench/env/lib/python3.10/site-packages/pymysql/connections.py", line 361, in __init__
    self.connect()
  File "/home/magic/frappe-bench/env/lib/python3.10/site-packages/pymysql/connections.py", line 669, in connect
    self._request_authentication()
  File "/home/magic/frappe-bench/env/lib/python3.10/site-packages/pymysql/connections.py", line 957, in _request_authentication
    auth_packet = self._read_packet()
  File "/home/magic/frappe-bench/env/lib/python3.10/site-packages/pymysql/connections.py", line 775, in _read_packet
    packet.raise_for_error()
  File "/home/magic/frappe-bench/env/lib/python3.10/site-packages/pymysql/protocol.py", line 219, in raise_for_error
    err.raise_mysql_exception(self._data)
  File "/home/magic/frappe-bench/env/lib/python3.10/site-packages/pymysql/err.py", line 150, in raise_mysql_exception
    raise errorclass(errno, errval)
pymysql.err.OperationalError: (1049, "Unknown database '_7c4e36808ec69197'")
2024-09-22 13:26:24,940 ERROR scheduler Exception in Enqueue Events for Site maigctable
Traceback (most recent call last):
  File "/home/magic/frappe-bench/apps/frappe/frappe/utils/scheduler.py", line 75, in enqueue_events_for_site
    if is_scheduler_inactive():
  File "/home/magic/frappe-bench/apps/frappe/frappe/utils/scheduler.py", line 117, in is_scheduler_inactive
    if is_scheduler_disabled(verbose=verbose):
  File "/home/magic/frappe-bench/apps/frappe/frappe/utils/scheduler.py", line 130, in is_scheduler_disabled
    frappe.db.get_single_value("System Settings", "enable_scheduler")
  File "/home/magic/frappe-bench/apps/frappe/frappe/database/database.py", line 834, in get_single_value
    ).run()
  File "/home/magic/frappe-bench/apps/frappe/frappe/query_builder/utils.py", line 87, in execute_query
    result = frappe.db.sql(query, params, *args, **kwargs)  # nosemgrep
  File "/home/magic/frappe-bench/apps/frappe/frappe/database/database.py", line 204, in sql
    self.connect()
  File "/home/magic/frappe-bench/apps/frappe/frappe/database/database.py", line 109, in connect
    self._conn: "MariadbConnection" | "PostgresConnection" = self.get_connection()
  File "/home/magic/frappe-bench/apps/frappe/frappe/database/mariadb/database.py", line 107, in get_connection
    conn = self._get_connection()
  File "/home/magic/frappe-bench/apps/frappe/frappe/database/mariadb/database.py", line 113, in _get_connection
    return self.create_connection()
  File "/home/magic/frappe-bench/apps/frappe/frappe/database/mariadb/database.py", line 116, in create_connection
    return pymysql.connect(**self.get_connection_settings())
  File "/home/magic/frappe-bench/env/lib/python3.10/site-packages/pymysql/connections.py", line 361, in __init__
    self.connect()
  File "/home/magic/frappe-bench/env/lib/python3.10/site-packages/pymysql/connections.py", line 669, in connect
    self._request_authentication()
  File "/home/magic/frappe-bench/env/lib/python3.10/site-packages/pymysql/connections.py", line 957, in _request_authentication
    auth_packet = self._read_packet()
  File "/home/magic/frappe-bench/env/lib/python3.10/site-packages/pymysql/connections.py", line 775, in _read_packet
    packet.raise_for_error()
  File "/home/magic/frappe-bench/env/lib/python3.10/site-packages/pymysql/protocol.py", line 219, in raise_for_error
    err.raise_mysql_exception(self._data)
  File "/home/magic/frappe-bench/env/lib/python3.10/site-packages/pymysql/err.py", line 150, in raise_mysql_exception
    raise errorclass(errno, errval)
pymysql.err.OperationalError: (1049, "Unknown database '_7c4e36808ec69197'")
2024-09-22 13:27:25,056 ERROR scheduler Exception in Enqueue Events for Site maigctable
Traceback (most recent call last):
  File "/home/magic/frappe-bench/apps/frappe/frappe/utils/scheduler.py", line 75, in enqueue_events_for_site
    if is_scheduler_inactive():
  File "/home/magic/frappe-bench/apps/frappe/frappe/utils/scheduler.py", line 117, in is_scheduler_inactive
    if is_scheduler_disabled(verbose=verbose):
  File "/home/magic/frappe-bench/apps/frappe/frappe/utils/scheduler.py", line 130, in is_scheduler_disabled
    frappe.db.get_single_value("System Settings", "enable_scheduler")
  File "/home/magic/frappe-bench/apps/frappe/frappe/database/database.py", line 834, in get_single_value
    ).run()
  File "/home/magic/frappe-bench/apps/frappe/frappe/query_builder/utils.py", line 87, in execute_query
    result = frappe.db.sql(query, params, *args, **kwargs)  # nosemgrep
  File "/home/magic/frappe-bench/apps/frappe/frappe/database/database.py", line 204, in sql
    self.connect()
  File "/home/magic/frappe-bench/apps/frappe/frappe/database/database.py", line 109, in connect
    self._conn: "MariadbConnection" | "PostgresConnection" = self.get_connection()
  File "/home/magic/frappe-bench/apps/frappe/frappe/database/mariadb/database.py", line 107, in get_connection
    conn = self._get_connection()
  File "/home/magic/frappe-bench/apps/frappe/frappe/database/mariadb/database.py", line 113, in _get_connection
    return self.create_connection()
  File "/home/magic/frappe-bench/apps/frappe/frappe/database/mariadb/database.py", line 116, in create_connection
    return pymysql.connect(**self.get_connection_settings())
  File "/home/magic/frappe-bench/env/lib/python3.10/site-packages/pymysql/connections.py", line 361, in __init__
    self.connect()
  File "/home/magic/frappe-bench/env/lib/python3.10/site-packages/pymysql/connections.py", line 669, in connect
    self._request_authentication()
  File "/home/magic/frappe-bench/env/lib/python3.10/site-packages/pymysql/connections.py", line 957, in _request_authentication
    auth_packet = self._read_packet()
  File "/home/magic/frappe-bench/env/lib/python3.10/site-packages/pymysql/connections.py", line 775, in _read_packet
    packet.raise_for_error()
  File "/home/magic/frappe-bench/env/lib/python3.10/site-packages/pymysql/protocol.py", line 219, in raise_for_error
    err.raise_mysql_exception(self._data)
  File "/home/magic/frappe-bench/env/lib/python3.10/site-packages/pymysql/err.py", line 150, in raise_mysql_exception
    raise errorclass(errno, errval)
pymysql.err.OperationalError: (1049, "Unknown database '_7c4e36808ec69197'")
2024-09-22 13:28:25,179 ERROR scheduler Exception in Enqueue Events for Site maigctable
Traceback (most recent call last):
  File "/home/magic/frappe-bench/apps/frappe/frappe/utils/scheduler.py", line 75, in enqueue_events_for_site
    if is_scheduler_inactive():
  File "/home/magic/frappe-bench/apps/frappe/frappe/utils/scheduler.py", line 117, in is_scheduler_inactive
    if is_scheduler_disabled(verbose=verbose):
  File "/home/magic/frappe-bench/apps/frappe/frappe/utils/scheduler.py", line 130, in is_scheduler_disabled
    frappe.db.get_single_value("System Settings", "enable_scheduler")
  File "/home/magic/frappe-bench/apps/frappe/frappe/database/database.py", line 834, in get_single_value
    ).run()
  File "/home/magic/frappe-bench/apps/frappe/frappe/query_builder/utils.py", line 87, in execute_query
    result = frappe.db.sql(query, params, *args, **kwargs)  # nosemgrep
  File "/home/magic/frappe-bench/apps/frappe/frappe/database/database.py", line 204, in sql
    self.connect()
  File "/home/magic/frappe-bench/apps/frappe/frappe/database/database.py", line 109, in connect
    self._conn: "MariadbConnection" | "PostgresConnection" = self.get_connection()
  File "/home/magic/frappe-bench/apps/frappe/frappe/database/mariadb/database.py", line 107, in get_connection
    conn = self._get_connection()
  File "/home/magic/frappe-bench/apps/frappe/frappe/database/mariadb/database.py", line 113, in _get_connection
    return self.create_connection()
  File "/home/magic/frappe-bench/apps/frappe/frappe/database/mariadb/database.py", line 116, in create_connection
    return pymysql.connect(**self.get_connection_settings())
  File "/home/magic/frappe-bench/env/lib/python3.10/site-packages/pymysql/connections.py", line 361, in __init__
    self.connect()
  File "/home/magic/frappe-bench/env/lib/python3.10/site-packages/pymysql/connections.py", line 669, in connect
    self._request_authentication()
  File "/home/magic/frappe-bench/env/lib/python3.10/site-packages/pymysql/connections.py", line 957, in _request_authentication
    auth_packet = self._read_packet()
  File "/home/magic/frappe-bench/env/lib/python3.10/site-packages/pymysql/connections.py", line 775, in _read_packet
    packet.raise_for_error()
  File "/home/magic/frappe-bench/env/lib/python3.10/site-packages/pymysql/protocol.py", line 219, in raise_for_error
    err.raise_mysql_exception(self._data)
  File "/home/magic/frappe-bench/env/lib/python3.10/site-packages/pymysql/err.py", line 150, in raise_mysql_exception
    raise errorclass(errno, errval)
pymysql.err.OperationalError: (1049, "Unknown database '_7c4e36808ec69197'")
2024-09-22 13:29:25,274 ERROR scheduler Exception in Enqueue Events for Site maigctable
Traceback (most recent call last):
  File "/home/magic/frappe-bench/apps/frappe/frappe/utils/scheduler.py", line 75, in enqueue_events_for_site
    if is_scheduler_inactive():
  File "/home/magic/frappe-bench/apps/frappe/frappe/utils/scheduler.py", line 117, in is_scheduler_inactive
    if is_scheduler_disabled(verbose=verbose):
  File "/home/magic/frappe-bench/apps/frappe/frappe/utils/scheduler.py", line 130, in is_scheduler_disabled
    frappe.db.get_single_value("System Settings", "enable_scheduler")
  File "/home/magic/frappe-bench/apps/frappe/frappe/database/database.py", line 834, in get_single_value
    ).run()
  File "/home/magic/frappe-bench/apps/frappe/frappe/query_builder/utils.py", line 87, in execute_query
    result = frappe.db.sql(query, params, *args, **kwargs)  # nosemgrep
  File "/home/magic/frappe-bench/apps/frappe/frappe/database/database.py", line 204, in sql
    self.connect()
  File "/home/magic/frappe-bench/apps/frappe/frappe/database/database.py", line 109, in connect
    self._conn: "MariadbConnection" | "PostgresConnection" = self.get_connection()
  File "/home/magic/frappe-bench/apps/frappe/frappe/database/mariadb/database.py", line 107, in get_connection
    conn = self._get_connection()
  File "/home/magic/frappe-bench/apps/frappe/frappe/database/mariadb/database.py", line 113, in _get_connection
    return self.create_connection()
  File "/home/magic/frappe-bench/apps/frappe/frappe/database/mariadb/database.py", line 116, in create_connection
    return pymysql.connect(**self.get_connection_settings())
  File "/home/magic/frappe-bench/env/lib/python3.10/site-packages/pymysql/connections.py", line 361, in __init__
    self.connect()
  File "/home/magic/frappe-bench/env/lib/python3.10/site-packages/pymysql/connections.py", line 669, in connect
    self._request_authentication()
  File "/home/magic/frappe-bench/env/lib/python3.10/site-packages/pymysql/connections.py", line 957, in _request_authentication
    auth_packet = self._read_packet()
  File "/home/magic/frappe-bench/env/lib/python3.10/site-packages/pymysql/connections.py", line 775, in _read_packet
    packet.raise_for_error()
  File "/home/magic/frappe-bench/env/lib/python3.10/site-packages/pymysql/protocol.py", line 219, in raise_for_error
    err.raise_mysql_exception(self._data)
  File "/home/magic/frappe-bench/env/lib/python3.10/site-packages/pymysql/err.py", line 150, in raise_mysql_exception
    raise errorclass(errno, errval)
pymysql.err.OperationalError: (1049, "Unknown database '_7c4e36808ec69197'")
2024-09-22 13:30:25,513 ERROR scheduler Exception in Enqueue Events for Site maigctable
Traceback (most recent call last):
  File "/home/magic/frappe-bench/apps/frappe/frappe/utils/scheduler.py", line 75, in enqueue_events_for_site
    if is_scheduler_inactive():
  File "/home/magic/frappe-bench/apps/frappe/frappe/utils/scheduler.py", line 117, in is_scheduler_inactive
    if is_scheduler_disabled(verbose=verbose):
  File "/home/magic/frappe-bench/apps/frappe/frappe/utils/scheduler.py", line 130, in is_scheduler_disabled
    frappe.db.get_single_value("System Settings", "enable_scheduler")
  File "/home/magic/frappe-bench/apps/frappe/frappe/database/database.py", line 834, in get_single_value
    ).run()
  File "/home/magic/frappe-bench/apps/frappe/frappe/query_builder/utils.py", line 87, in execute_query
    result = frappe.db.sql(query, params, *args, **kwargs)  # nosemgrep
  File "/home/magic/frappe-bench/apps/frappe/frappe/database/database.py", line 204, in sql
    self.connect()
  File "/home/magic/frappe-bench/apps/frappe/frappe/database/database.py", line 109, in connect
    self._conn: "MariadbConnection" | "PostgresConnection" = self.get_connection()
  File "/home/magic/frappe-bench/apps/frappe/frappe/database/mariadb/database.py", line 107, in get_connection
    conn = self._get_connection()
  File "/home/magic/frappe-bench/apps/frappe/frappe/database/mariadb/database.py", line 113, in _get_connection
    return self.create_connection()
  File "/home/magic/frappe-bench/apps/frappe/frappe/database/mariadb/database.py", line 116, in create_connection
    return pymysql.connect(**self.get_connection_settings())
  File "/home/magic/frappe-bench/env/lib/python3.10/site-packages/pymysql/connections.py", line 361, in __init__
    self.connect()
  File "/home/magic/frappe-bench/env/lib/python3.10/site-packages/pymysql/connections.py", line 669, in connect
    self._request_authentication()
  File "/home/magic/frappe-bench/env/lib/python3.10/site-packages/pymysql/connections.py", line 957, in _request_authentication
    auth_packet = self._read_packet()
  File "/home/magic/frappe-bench/env/lib/python3.10/site-packages/pymysql/connections.py", line 775, in _read_packet
    packet.raise_for_error()
  File "/home/magic/frappe-bench/env/lib/python3.10/site-packages/pymysql/protocol.py", line 219, in raise_for_error
    err.raise_mysql_exception(self._data)
  File "/home/magic/frappe-bench/env/lib/python3.10/site-packages/pymysql/err.py", line 150, in raise_mysql_exception
    raise errorclass(errno, errval)
pymysql.err.OperationalError: (1049, "Unknown database '_7c4e36808ec69197'")
2024-09-22 13:31:25,676 ERROR scheduler Exception in Enqueue Events for Site maigctable
Traceback (most recent call last):
  File "/home/magic/frappe-bench/apps/frappe/frappe/utils/scheduler.py", line 75, in enqueue_events_for_site
    if is_scheduler_inactive():
  File "/home/magic/frappe-bench/apps/frappe/frappe/utils/scheduler.py", line 117, in is_scheduler_inactive
    if is_scheduler_disabled(verbose=verbose):
  File "/home/magic/frappe-bench/apps/frappe/frappe/utils/scheduler.py", line 130, in is_scheduler_disabled
    frappe.db.get_single_value("System Settings", "enable_scheduler")
  File "/home/magic/frappe-bench/apps/frappe/frappe/database/database.py", line 834, in get_single_value
    ).run()
  File "/home/magic/frappe-bench/apps/frappe/frappe/query_builder/utils.py", line 87, in execute_query
    result = frappe.db.sql(query, params, *args, **kwargs)  # nosemgrep
  File "/home/magic/frappe-bench/apps/frappe/frappe/database/database.py", line 204, in sql
    self.connect()
  File "/home/magic/frappe-bench/apps/frappe/frappe/database/database.py", line 109, in connect
    self._conn: "MariadbConnection" | "PostgresConnection" = self.get_connection()
  File "/home/magic/frappe-bench/apps/frappe/frappe/database/mariadb/database.py", line 107, in get_connection
    conn = self._get_connection()
  File "/home/magic/frappe-bench/apps/frappe/frappe/database/mariadb/database.py", line 113, in _get_connection
    return self.create_connection()
  File "/home/magic/frappe-bench/apps/frappe/frappe/database/mariadb/database.py", line 116, in create_connection
    return pymysql.connect(**self.get_connection_settings())
  File "/home/magic/frappe-bench/env/lib/python3.10/site-packages/pymysql/connections.py", line 361, in __init__
    self.connect()
  File "/home/magic/frappe-bench/env/lib/python3.10/site-packages/pymysql/connections.py", line 669, in connect
    self._request_authentication()
  File "/home/magic/frappe-bench/env/lib/python3.10/site-packages/pymysql/connections.py", line 957, in _request_authentication
    auth_packet = self._read_packet()
  File "/home/magic/frappe-bench/env/lib/python3.10/site-packages/pymysql/connections.py", line 775, in _read_packet
    packet.raise_for_error()
  File "/home/magic/frappe-bench/env/lib/python3.10/site-packages/pymysql/protocol.py", line 219, in raise_for_error
    err.raise_mysql_exception(self._data)
  File "/home/magic/frappe-bench/env/lib/python3.10/site-packages/pymysql/err.py", line 150, in raise_mysql_exception
    raise errorclass(errno, errval)
pymysql.err.OperationalError: (1049, "Unknown database '_7c4e36808ec69197'")
2024-09-22 13:32:25,688 ERROR scheduler Exception in Enqueue Events for Site maigctable
Traceback (most recent call last):
  File "/home/magic/frappe-bench/apps/frappe/frappe/utils/scheduler.py", line 75, in enqueue_events_for_site
    if is_scheduler_inactive():
  File "/home/magic/frappe-bench/apps/frappe/frappe/utils/scheduler.py", line 117, in is_scheduler_inactive
    if is_scheduler_disabled(verbose=verbose):
  File "/home/magic/frappe-bench/apps/frappe/frappe/utils/scheduler.py", line 130, in is_scheduler_disabled
    frappe.db.get_single_value("System Settings", "enable_scheduler")
  File "/home/magic/frappe-bench/apps/frappe/frappe/database/database.py", line 834, in get_single_value
    ).run()
  File "/home/magic/frappe-bench/apps/frappe/frappe/query_builder/utils.py", line 87, in execute_query
    result = frappe.db.sql(query, params, *args, **kwargs)  # nosemgrep
  File "/home/magic/frappe-bench/apps/frappe/frappe/database/database.py", line 204, in sql
    self.connect()
  File "/home/magic/frappe-bench/apps/frappe/frappe/database/database.py", line 109, in connect
    self._conn: "MariadbConnection" | "PostgresConnection" = self.get_connection()
  File "/home/magic/frappe-bench/apps/frappe/frappe/database/mariadb/database.py", line 107, in get_connection
    conn = self._get_connection()
  File "/home/magic/frappe-bench/apps/frappe/frappe/database/mariadb/database.py", line 113, in _get_connection
    return self.create_connection()
  File "/home/magic/frappe-bench/apps/frappe/frappe/database/mariadb/database.py", line 116, in create_connection
    return pymysql.connect(**self.get_connection_settings())
  File "/home/magic/frappe-bench/env/lib/python3.10/site-packages/pymysql/connections.py", line 361, in __init__
    self.connect()
  File "/home/magic/frappe-bench/env/lib/python3.10/site-packages/pymysql/connections.py", line 669, in connect
    self._request_authentication()
  File "/home/magic/frappe-bench/env/lib/python3.10/site-packages/pymysql/connections.py", line 957, in _request_authentication
    auth_packet = self._read_packet()
  File "/home/magic/frappe-bench/env/lib/python3.10/site-packages/pymysql/connections.py", line 775, in _read_packet
    packet.raise_for_error()
  File "/home/magic/frappe-bench/env/lib/python3.10/site-packages/pymysql/protocol.py", line 219, in raise_for_error
    err.raise_mysql_exception(self._data)
  File "/home/magic/frappe-bench/env/lib/python3.10/site-packages/pymysql/err.py", line 150, in raise_mysql_exception
    raise errorclass(errno, errval)
pymysql.err.OperationalError: (1049, "Unknown database '_7c4e36808ec69197'")
2024-09-22 13:33:25,737 ERROR scheduler Exception in Enqueue Events for Site maigctable
Traceback (most recent call last):
  File "/home/magic/frappe-bench/apps/frappe/frappe/utils/scheduler.py", line 75, in enqueue_events_for_site
    if is_scheduler_inactive():
  File "/home/magic/frappe-bench/apps/frappe/frappe/utils/scheduler.py", line 117, in is_scheduler_inactive
    if is_scheduler_disabled(verbose=verbose):
  File "/home/magic/frappe-bench/apps/frappe/frappe/utils/scheduler.py", line 130, in is_scheduler_disabled
    frappe.db.get_single_value("System Settings", "enable_scheduler")
  File "/home/magic/frappe-bench/apps/frappe/frappe/database/database.py", line 834, in get_single_value
    ).run()
  File "/home/magic/frappe-bench/apps/frappe/frappe/query_builder/utils.py", line 87, in execute_query
    result = frappe.db.sql(query, params, *args, **kwargs)  # nosemgrep
  File "/home/magic/frappe-bench/apps/frappe/frappe/database/database.py", line 204, in sql
    self.connect()
  File "/home/magic/frappe-bench/apps/frappe/frappe/database/database.py", line 109, in connect
    self._conn: "MariadbConnection" | "PostgresConnection" = self.get_connection()
  File "/home/magic/frappe-bench/apps/frappe/frappe/database/mariadb/database.py", line 107, in get_connection
    conn = self._get_connection()
  File "/home/magic/frappe-bench/apps/frappe/frappe/database/mariadb/database.py", line 113, in _get_connection
    return self.create_connection()
  File "/home/magic/frappe-bench/apps/frappe/frappe/database/mariadb/database.py", line 116, in create_connection
    return pymysql.connect(**self.get_connection_settings())
  File "/home/magic/frappe-bench/env/lib/python3.10/site-packages/pymysql/connections.py", line 361, in __init__
    self.connect()
  File "/home/magic/frappe-bench/env/lib/python3.10/site-packages/pymysql/connections.py", line 669, in connect
    self._request_authentication()
  File "/home/magic/frappe-bench/env/lib/python3.10/site-packages/pymysql/connections.py", line 957, in _request_authentication
    auth_packet = self._read_packet()
  File "/home/magic/frappe-bench/env/lib/python3.10/site-packages/pymysql/connections.py", line 775, in _read_packet
    packet.raise_for_error()
  File "/home/magic/frappe-bench/env/lib/python3.10/site-packages/pymysql/protocol.py", line 219, in raise_for_error
    err.raise_mysql_exception(self._data)
  File "/home/magic/frappe-bench/env/lib/python3.10/site-packages/pymysql/err.py", line 150, in raise_mysql_exception
    raise errorclass(errno, errval)
pymysql.err.OperationalError: (1049, "Unknown database '_7c4e36808ec69197'")
2024-09-22 13:34:25,866 ERROR scheduler Exception in Enqueue Events for Site maigctable
Traceback (most recent call last):
  File "/home/magic/frappe-bench/apps/frappe/frappe/utils/scheduler.py", line 75, in enqueue_events_for_site
    if is_scheduler_inactive():
  File "/home/magic/frappe-bench/apps/frappe/frappe/utils/scheduler.py", line 117, in is_scheduler_inactive
    if is_scheduler_disabled(verbose=verbose):
  File "/home/magic/frappe-bench/apps/frappe/frappe/utils/scheduler.py", line 130, in is_scheduler_disabled
    frappe.db.get_single_value("System Settings", "enable_scheduler")
  File "/home/magic/frappe-bench/apps/frappe/frappe/database/database.py", line 834, in get_single_value
    ).run()
  File "/home/magic/frappe-bench/apps/frappe/frappe/query_builder/utils.py", line 87, in execute_query
    result = frappe.db.sql(query, params, *args, **kwargs)  # nosemgrep
  File "/home/magic/frappe-bench/apps/frappe/frappe/database/database.py", line 204, in sql
    self.connect()
  File "/home/magic/frappe-bench/apps/frappe/frappe/database/database.py", line 109, in connect
    self._conn: "MariadbConnection" | "PostgresConnection" = self.get_connection()
  File "/home/magic/frappe-bench/apps/frappe/frappe/database/mariadb/database.py", line 107, in get_connection
    conn = self._get_connection()
  File "/home/magic/frappe-bench/apps/frappe/frappe/database/mariadb/database.py", line 113, in _get_connection
    return self.create_connection()
  File "/home/magic/frappe-bench/apps/frappe/frappe/database/mariadb/database.py", line 116, in create_connection
    return pymysql.connect(**self.get_connection_settings())
  File "/home/magic/frappe-bench/env/lib/python3.10/site-packages/pymysql/connections.py", line 361, in __init__
    self.connect()
  File "/home/magic/frappe-bench/env/lib/python3.10/site-packages/pymysql/connections.py", line 669, in connect
    self._request_authentication()
  File "/home/magic/frappe-bench/env/lib/python3.10/site-packages/pymysql/connections.py", line 957, in _request_authentication
    auth_packet = self._read_packet()
  File "/home/magic/frappe-bench/env/lib/python3.10/site-packages/pymysql/connections.py", line 775, in _read_packet
    packet.raise_for_error()
  File "/home/magic/frappe-bench/env/lib/python3.10/site-packages/pymysql/protocol.py", line 219, in raise_for_error
    err.raise_mysql_exception(self._data)
  File "/home/magic/frappe-bench/env/lib/python3.10/site-packages/pymysql/err.py", line 150, in raise_mysql_exception
    raise errorclass(errno, errval)
pymysql.err.OperationalError: (1049, "Unknown database '_7c4e36808ec69197'")
2024-09-22 13:35:25,982 ERROR scheduler Exception in Enqueue Events for Site maigctable
Traceback (most recent call last):
  File "/home/magic/frappe-bench/apps/frappe/frappe/utils/scheduler.py", line 75, in enqueue_events_for_site
    if is_scheduler_inactive():
  File "/home/magic/frappe-bench/apps/frappe/frappe/utils/scheduler.py", line 117, in is_scheduler_inactive
    if is_scheduler_disabled(verbose=verbose):
  File "/home/magic/frappe-bench/apps/frappe/frappe/utils/scheduler.py", line 130, in is_scheduler_disabled
    frappe.db.get_single_value("System Settings", "enable_scheduler")
  File "/home/magic/frappe-bench/apps/frappe/frappe/database/database.py", line 834, in get_single_value
    ).run()
  File "/home/magic/frappe-bench/apps/frappe/frappe/query_builder/utils.py", line 87, in execute_query
    result = frappe.db.sql(query, params, *args, **kwargs)  # nosemgrep
  File "/home/magic/frappe-bench/apps/frappe/frappe/database/database.py", line 204, in sql
    self.connect()
  File "/home/magic/frappe-bench/apps/frappe/frappe/database/database.py", line 109, in connect
    self._conn: "MariadbConnection" | "PostgresConnection" = self.get_connection()
  File "/home/magic/frappe-bench/apps/frappe/frappe/database/mariadb/database.py", line 107, in get_connection
    conn = self._get_connection()
  File "/home/magic/frappe-bench/apps/frappe/frappe/database/mariadb/database.py", line 113, in _get_connection
    return self.create_connection()
  File "/home/magic/frappe-bench/apps/frappe/frappe/database/mariadb/database.py", line 116, in create_connection
    return pymysql.connect(**self.get_connection_settings())
  File "/home/magic/frappe-bench/env/lib/python3.10/site-packages/pymysql/connections.py", line 361, in __init__
    self.connect()
  File "/home/magic/frappe-bench/env/lib/python3.10/site-packages/pymysql/connections.py", line 669, in connect
    self._request_authentication()
  File "/home/magic/frappe-bench/env/lib/python3.10/site-packages/pymysql/connections.py", line 957, in _request_authentication
    auth_packet = self._read_packet()
  File "/home/magic/frappe-bench/env/lib/python3.10/site-packages/pymysql/connections.py", line 775, in _read_packet
    packet.raise_for_error()
  File "/home/magic/frappe-bench/env/lib/python3.10/site-packages/pymysql/protocol.py", line 219, in raise_for_error
    err.raise_mysql_exception(self._data)
  File "/home/magic/frappe-bench/env/lib/python3.10/site-packages/pymysql/err.py", line 150, in raise_mysql_exception
    raise errorclass(errno, errval)
pymysql.err.OperationalError: (1049, "Unknown database '_7c4e36808ec69197'")
2024-09-22 13:36:26,085 ERROR scheduler Exception in Enqueue Events for Site maigctable
Traceback (most recent call last):
  File "/home/magic/frappe-bench/apps/frappe/frappe/utils/scheduler.py", line 75, in enqueue_events_for_site
    if is_scheduler_inactive():
  File "/home/magic/frappe-bench/apps/frappe/frappe/utils/scheduler.py", line 117, in is_scheduler_inactive
    if is_scheduler_disabled(verbose=verbose):
  File "/home/magic/frappe-bench/apps/frappe/frappe/utils/scheduler.py", line 130, in is_scheduler_disabled
    frappe.db.get_single_value("System Settings", "enable_scheduler")
  File "/home/magic/frappe-bench/apps/frappe/frappe/database/database.py", line 834, in get_single_value
    ).run()
  File "/home/magic/frappe-bench/apps/frappe/frappe/query_builder/utils.py", line 87, in execute_query
    result = frappe.db.sql(query, params, *args, **kwargs)  # nosemgrep
  File "/home/magic/frappe-bench/apps/frappe/frappe/database/database.py", line 204, in sql
    self.connect()
  File "/home/magic/frappe-bench/apps/frappe/frappe/database/database.py", line 109, in connect
    self._conn: "MariadbConnection" | "PostgresConnection" = self.get_connection()
  File "/home/magic/frappe-bench/apps/frappe/frappe/database/mariadb/database.py", line 107, in get_connection
    conn = self._get_connection()
  File "/home/magic/frappe-bench/apps/frappe/frappe/database/mariadb/database.py", line 113, in _get_connection
    return self.create_connection()
  File "/home/magic/frappe-bench/apps/frappe/frappe/database/mariadb/database.py", line 116, in create_connection
    return pymysql.connect(**self.get_connection_settings())
  File "/home/magic/frappe-bench/env/lib/python3.10/site-packages/pymysql/connections.py", line 361, in __init__
    self.connect()
  File "/home/magic/frappe-bench/env/lib/python3.10/site-packages/pymysql/connections.py", line 669, in connect
    self._request_authentication()
  File "/home/magic/frappe-bench/env/lib/python3.10/site-packages/pymysql/connections.py", line 957, in _request_authentication
    auth_packet = self._read_packet()
  File "/home/magic/frappe-bench/env/lib/python3.10/site-packages/pymysql/connections.py", line 775, in _read_packet
    packet.raise_for_error()
  File "/home/magic/frappe-bench/env/lib/python3.10/site-packages/pymysql/protocol.py", line 219, in raise_for_error
    err.raise_mysql_exception(self._data)
  File "/home/magic/frappe-bench/env/lib/python3.10/site-packages/pymysql/err.py", line 150, in raise_mysql_exception
    raise errorclass(errno, errval)
pymysql.err.OperationalError: (1049, "Unknown database '_7c4e36808ec69197'")
2024-09-22 13:37:26,165 ERROR scheduler Exception in Enqueue Events for Site maigctable
Traceback (most recent call last):
  File "/home/magic/frappe-bench/apps/frappe/frappe/utils/scheduler.py", line 75, in enqueue_events_for_site
    if is_scheduler_inactive():
  File "/home/magic/frappe-bench/apps/frappe/frappe/utils/scheduler.py", line 117, in is_scheduler_inactive
    if is_scheduler_disabled(verbose=verbose):
  File "/home/magic/frappe-bench/apps/frappe/frappe/utils/scheduler.py", line 130, in is_scheduler_disabled
    frappe.db.get_single_value("System Settings", "enable_scheduler")
  File "/home/magic/frappe-bench/apps/frappe/frappe/database/database.py", line 834, in get_single_value
    ).run()
  File "/home/magic/frappe-bench/apps/frappe/frappe/query_builder/utils.py", line 87, in execute_query
    result = frappe.db.sql(query, params, *args, **kwargs)  # nosemgrep
  File "/home/magic/frappe-bench/apps/frappe/frappe/database/database.py", line 204, in sql
    self.connect()
  File "/home/magic/frappe-bench/apps/frappe/frappe/database/database.py", line 109, in connect
    self._conn: "MariadbConnection" | "PostgresConnection" = self.get_connection()
  File "/home/magic/frappe-bench/apps/frappe/frappe/database/mariadb/database.py", line 107, in get_connection
    conn = self._get_connection()
  File "/home/magic/frappe-bench/apps/frappe/frappe/database/mariadb/database.py", line 113, in _get_connection
    return self.create_connection()
  File "/home/magic/frappe-bench/apps/frappe/frappe/database/mariadb/database.py", line 116, in create_connection
    return pymysql.connect(**self.get_connection_settings())
  File "/home/magic/frappe-bench/env/lib/python3.10/site-packages/pymysql/connections.py", line 361, in __init__
    self.connect()
  File "/home/magic/frappe-bench/env/lib/python3.10/site-packages/pymysql/connections.py", line 669, in connect
    self._request_authentication()
  File "/home/magic/frappe-bench/env/lib/python3.10/site-packages/pymysql/connections.py", line 957, in _request_authentication
    auth_packet = self._read_packet()
  File "/home/magic/frappe-bench/env/lib/python3.10/site-packages/pymysql/connections.py", line 775, in _read_packet
    packet.raise_for_error()
  File "/home/magic/frappe-bench/env/lib/python3.10/site-packages/pymysql/protocol.py", line 219, in raise_for_error
    err.raise_mysql_exception(self._data)
  File "/home/magic/frappe-bench/env/lib/python3.10/site-packages/pymysql/err.py", line 150, in raise_mysql_exception
    raise errorclass(errno, errval)
pymysql.err.OperationalError: (1049, "Unknown database '_7c4e36808ec69197'")
2024-09-22 13:38:26,265 ERROR scheduler Exception in Enqueue Events for Site maigctable
Traceback (most recent call last):
  File "/home/magic/frappe-bench/apps/frappe/frappe/utils/scheduler.py", line 75, in enqueue_events_for_site
    if is_scheduler_inactive():
  File "/home/magic/frappe-bench/apps/frappe/frappe/utils/scheduler.py", line 117, in is_scheduler_inactive
    if is_scheduler_disabled(verbose=verbose):
  File "/home/magic/frappe-bench/apps/frappe/frappe/utils/scheduler.py", line 130, in is_scheduler_disabled
    frappe.db.get_single_value("System Settings", "enable_scheduler")
  File "/home/magic/frappe-bench/apps/frappe/frappe/database/database.py", line 834, in get_single_value
    ).run()
  File "/home/magic/frappe-bench/apps/frappe/frappe/query_builder/utils.py", line 87, in execute_query
    result = frappe.db.sql(query, params, *args, **kwargs)  # nosemgrep
  File "/home/magic/frappe-bench/apps/frappe/frappe/database/database.py", line 204, in sql
    self.connect()
  File "/home/magic/frappe-bench/apps/frappe/frappe/database/database.py", line 109, in connect
    self._conn: "MariadbConnection" | "PostgresConnection" = self.get_connection()
  File "/home/magic/frappe-bench/apps/frappe/frappe/database/mariadb/database.py", line 107, in get_connection
    conn = self._get_connection()
  File "/home/magic/frappe-bench/apps/frappe/frappe/database/mariadb/database.py", line 113, in _get_connection
    return self.create_connection()
  File "/home/magic/frappe-bench/apps/frappe/frappe/database/mariadb/database.py", line 116, in create_connection
    return pymysql.connect(**self.get_connection_settings())
  File "/home/magic/frappe-bench/env/lib/python3.10/site-packages/pymysql/connections.py", line 361, in __init__
    self.connect()
  File "/home/magic/frappe-bench/env/lib/python3.10/site-packages/pymysql/connections.py", line 669, in connect
    self._request_authentication()
  File "/home/magic/frappe-bench/env/lib/python3.10/site-packages/pymysql/connections.py", line 957, in _request_authentication
    auth_packet = self._read_packet()
  File "/home/magic/frappe-bench/env/lib/python3.10/site-packages/pymysql/connections.py", line 775, in _read_packet
    packet.raise_for_error()
  File "/home/magic/frappe-bench/env/lib/python3.10/site-packages/pymysql/protocol.py", line 219, in raise_for_error
    err.raise_mysql_exception(self._data)
  File "/home/magic/frappe-bench/env/lib/python3.10/site-packages/pymysql/err.py", line 150, in raise_mysql_exception
    raise errorclass(errno, errval)
pymysql.err.OperationalError: (1049, "Unknown database '_7c4e36808ec69197'")
2024-09-22 13:39:26,389 ERROR scheduler Exception in Enqueue Events for Site maigctable
Traceback (most recent call last):
  File "/home/magic/frappe-bench/apps/frappe/frappe/utils/scheduler.py", line 75, in enqueue_events_for_site
    if is_scheduler_inactive():
  File "/home/magic/frappe-bench/apps/frappe/frappe/utils/scheduler.py", line 117, in is_scheduler_inactive
    if is_scheduler_disabled(verbose=verbose):
  File "/home/magic/frappe-bench/apps/frappe/frappe/utils/scheduler.py", line 130, in is_scheduler_disabled
    frappe.db.get_single_value("System Settings", "enable_scheduler")
  File "/home/magic/frappe-bench/apps/frappe/frappe/database/database.py", line 834, in get_single_value
    ).run()
  File "/home/magic/frappe-bench/apps/frappe/frappe/query_builder/utils.py", line 87, in execute_query
    result = frappe.db.sql(query, params, *args, **kwargs)  # nosemgrep
  File "/home/magic/frappe-bench/apps/frappe/frappe/database/database.py", line 204, in sql
    self.connect()
  File "/home/magic/frappe-bench/apps/frappe/frappe/database/database.py", line 109, in connect
    self._conn: "MariadbConnection" | "PostgresConnection" = self.get_connection()
  File "/home/magic/frappe-bench/apps/frappe/frappe/database/mariadb/database.py", line 107, in get_connection
    conn = self._get_connection()
  File "/home/magic/frappe-bench/apps/frappe/frappe/database/mariadb/database.py", line 113, in _get_connection
    return self.create_connection()
  File "/home/magic/frappe-bench/apps/frappe/frappe/database/mariadb/database.py", line 116, in create_connection
    return pymysql.connect(**self.get_connection_settings())
  File "/home/magic/frappe-bench/env/lib/python3.10/site-packages/pymysql/connections.py", line 361, in __init__
    self.connect()
  File "/home/magic/frappe-bench/env/lib/python3.10/site-packages/pymysql/connections.py", line 669, in connect
    self._request_authentication()
  File "/home/magic/frappe-bench/env/lib/python3.10/site-packages/pymysql/connections.py", line 957, in _request_authentication
    auth_packet = self._read_packet()
  File "/home/magic/frappe-bench/env/lib/python3.10/site-packages/pymysql/connections.py", line 775, in _read_packet
    packet.raise_for_error()
  File "/home/magic/frappe-bench/env/lib/python3.10/site-packages/pymysql/protocol.py", line 219, in raise_for_error
    err.raise_mysql_exception(self._data)
  File "/home/magic/frappe-bench/env/lib/python3.10/site-packages/pymysql/err.py", line 150, in raise_mysql_exception
    raise errorclass(errno, errval)
pymysql.err.OperationalError: (1049, "Unknown database '_7c4e36808ec69197'")
2024-09-22 13:40:26,484 ERROR scheduler Exception in Enqueue Events for Site maigctable
Traceback (most recent call last):
  File "/home/magic/frappe-bench/apps/frappe/frappe/utils/scheduler.py", line 75, in enqueue_events_for_site
    if is_scheduler_inactive():
  File "/home/magic/frappe-bench/apps/frappe/frappe/utils/scheduler.py", line 117, in is_scheduler_inactive
    if is_scheduler_disabled(verbose=verbose):
  File "/home/magic/frappe-bench/apps/frappe/frappe/utils/scheduler.py", line 130, in is_scheduler_disabled
    frappe.db.get_single_value("System Settings", "enable_scheduler")
  File "/home/magic/frappe-bench/apps/frappe/frappe/database/database.py", line 834, in get_single_value
    ).run()
  File "/home/magic/frappe-bench/apps/frappe/frappe/query_builder/utils.py", line 87, in execute_query
    result = frappe.db.sql(query, params, *args, **kwargs)  # nosemgrep
  File "/home/magic/frappe-bench/apps/frappe/frappe/database/database.py", line 204, in sql
    self.connect()
  File "/home/magic/frappe-bench/apps/frappe/frappe/database/database.py", line 109, in connect
    self._conn: "MariadbConnection" | "PostgresConnection" = self.get_connection()
  File "/home/magic/frappe-bench/apps/frappe/frappe/database/mariadb/database.py", line 107, in get_connection
    conn = self._get_connection()
  File "/home/magic/frappe-bench/apps/frappe/frappe/database/mariadb/database.py", line 113, in _get_connection
    return self.create_connection()
  File "/home/magic/frappe-bench/apps/frappe/frappe/database/mariadb/database.py", line 116, in create_connection
    return pymysql.connect(**self.get_connection_settings())
  File "/home/magic/frappe-bench/env/lib/python3.10/site-packages/pymysql/connections.py", line 361, in __init__
    self.connect()
  File "/home/magic/frappe-bench/env/lib/python3.10/site-packages/pymysql/connections.py", line 669, in connect
    self._request_authentication()
  File "/home/magic/frappe-bench/env/lib/python3.10/site-packages/pymysql/connections.py", line 957, in _request_authentication
    auth_packet = self._read_packet()
  File "/home/magic/frappe-bench/env/lib/python3.10/site-packages/pymysql/connections.py", line 775, in _read_packet
    packet.raise_for_error()
  File "/home/magic/frappe-bench/env/lib/python3.10/site-packages/pymysql/protocol.py", line 219, in raise_for_error
    err.raise_mysql_exception(self._data)
  File "/home/magic/frappe-bench/env/lib/python3.10/site-packages/pymysql/err.py", line 150, in raise_mysql_exception
    raise errorclass(errno, errval)
pymysql.err.OperationalError: (1049, "Unknown database '_7c4e36808ec69197'")
2024-09-22 13:41:26,509 ERROR scheduler Exception in Enqueue Events for Site maigctable
Traceback (most recent call last):
  File "/home/magic/frappe-bench/apps/frappe/frappe/utils/scheduler.py", line 75, in enqueue_events_for_site
    if is_scheduler_inactive():
  File "/home/magic/frappe-bench/apps/frappe/frappe/utils/scheduler.py", line 117, in is_scheduler_inactive
    if is_scheduler_disabled(verbose=verbose):
  File "/home/magic/frappe-bench/apps/frappe/frappe/utils/scheduler.py", line 130, in is_scheduler_disabled
    frappe.db.get_single_value("System Settings", "enable_scheduler")
  File "/home/magic/frappe-bench/apps/frappe/frappe/database/database.py", line 834, in get_single_value
    ).run()
  File "/home/magic/frappe-bench/apps/frappe/frappe/query_builder/utils.py", line 87, in execute_query
    result = frappe.db.sql(query, params, *args, **kwargs)  # nosemgrep
  File "/home/magic/frappe-bench/apps/frappe/frappe/database/database.py", line 204, in sql
    self.connect()
  File "/home/magic/frappe-bench/apps/frappe/frappe/database/database.py", line 109, in connect
    self._conn: "MariadbConnection" | "PostgresConnection" = self.get_connection()
  File "/home/magic/frappe-bench/apps/frappe/frappe/database/mariadb/database.py", line 107, in get_connection
    conn = self._get_connection()
  File "/home/magic/frappe-bench/apps/frappe/frappe/database/mariadb/database.py", line 113, in _get_connection
    return self.create_connection()
  File "/home/magic/frappe-bench/apps/frappe/frappe/database/mariadb/database.py", line 116, in create_connection
    return pymysql.connect(**self.get_connection_settings())
  File "/home/magic/frappe-bench/env/lib/python3.10/site-packages/pymysql/connections.py", line 361, in __init__
    self.connect()
  File "/home/magic/frappe-bench/env/lib/python3.10/site-packages/pymysql/connections.py", line 669, in connect
    self._request_authentication()
  File "/home/magic/frappe-bench/env/lib/python3.10/site-packages/pymysql/connections.py", line 957, in _request_authentication
    auth_packet = self._read_packet()
  File "/home/magic/frappe-bench/env/lib/python3.10/site-packages/pymysql/connections.py", line 775, in _read_packet
    packet.raise_for_error()
  File "/home/magic/frappe-bench/env/lib/python3.10/site-packages/pymysql/protocol.py", line 219, in raise_for_error
    err.raise_mysql_exception(self._data)
  File "/home/magic/frappe-bench/env/lib/python3.10/site-packages/pymysql/err.py", line 150, in raise_mysql_exception
    raise errorclass(errno, errval)
pymysql.err.OperationalError: (1049, "Unknown database '_7c4e36808ec69197'")
2024-09-22 13:42:26,633 ERROR scheduler Exception in Enqueue Events for Site maigctable
Traceback (most recent call last):
  File "/home/magic/frappe-bench/apps/frappe/frappe/utils/scheduler.py", line 75, in enqueue_events_for_site
    if is_scheduler_inactive():
  File "/home/magic/frappe-bench/apps/frappe/frappe/utils/scheduler.py", line 117, in is_scheduler_inactive
    if is_scheduler_disabled(verbose=verbose):
  File "/home/magic/frappe-bench/apps/frappe/frappe/utils/scheduler.py", line 130, in is_scheduler_disabled
    frappe.db.get_single_value("System Settings", "enable_scheduler")
  File "/home/magic/frappe-bench/apps/frappe/frappe/database/database.py", line 834, in get_single_value
    ).run()
  File "/home/magic/frappe-bench/apps/frappe/frappe/query_builder/utils.py", line 87, in execute_query
    result = frappe.db.sql(query, params, *args, **kwargs)  # nosemgrep
  File "/home/magic/frappe-bench/apps/frappe/frappe/database/database.py", line 204, in sql
    self.connect()
  File "/home/magic/frappe-bench/apps/frappe/frappe/database/database.py", line 109, in connect
    self._conn: "MariadbConnection" | "PostgresConnection" = self.get_connection()
  File "/home/magic/frappe-bench/apps/frappe/frappe/database/mariadb/database.py", line 107, in get_connection
    conn = self._get_connection()
  File "/home/magic/frappe-bench/apps/frappe/frappe/database/mariadb/database.py", line 113, in _get_connection
    return self.create_connection()
  File "/home/magic/frappe-bench/apps/frappe/frappe/database/mariadb/database.py", line 116, in create_connection
    return pymysql.connect(**self.get_connection_settings())
  File "/home/magic/frappe-bench/env/lib/python3.10/site-packages/pymysql/connections.py", line 361, in __init__
    self.connect()
  File "/home/magic/frappe-bench/env/lib/python3.10/site-packages/pymysql/connections.py", line 669, in connect
    self._request_authentication()
  File "/home/magic/frappe-bench/env/lib/python3.10/site-packages/pymysql/connections.py", line 957, in _request_authentication
    auth_packet = self._read_packet()
  File "/home/magic/frappe-bench/env/lib/python3.10/site-packages/pymysql/connections.py", line 775, in _read_packet
    packet.raise_for_error()
  File "/home/magic/frappe-bench/env/lib/python3.10/site-packages/pymysql/protocol.py", line 219, in raise_for_error
    err.raise_mysql_exception(self._data)
  File "/home/magic/frappe-bench/env/lib/python3.10/site-packages/pymysql/err.py", line 150, in raise_mysql_exception
    raise errorclass(errno, errval)
pymysql.err.OperationalError: (1049, "Unknown database '_7c4e36808ec69197'")
2024-09-22 13:43:26,759 ERROR scheduler Exception in Enqueue Events for Site maigctable
Traceback (most recent call last):
  File "/home/magic/frappe-bench/apps/frappe/frappe/utils/scheduler.py", line 75, in enqueue_events_for_site
    if is_scheduler_inactive():
  File "/home/magic/frappe-bench/apps/frappe/frappe/utils/scheduler.py", line 117, in is_scheduler_inactive
    if is_scheduler_disabled(verbose=verbose):
  File "/home/magic/frappe-bench/apps/frappe/frappe/utils/scheduler.py", line 130, in is_scheduler_disabled
    frappe.db.get_single_value("System Settings", "enable_scheduler")
  File "/home/magic/frappe-bench/apps/frappe/frappe/database/database.py", line 834, in get_single_value
    ).run()
  File "/home/magic/frappe-bench/apps/frappe/frappe/query_builder/utils.py", line 87, in execute_query
    result = frappe.db.sql(query, params, *args, **kwargs)  # nosemgrep
  File "/home/magic/frappe-bench/apps/frappe/frappe/database/database.py", line 204, in sql
    self.connect()
  File "/home/magic/frappe-bench/apps/frappe/frappe/database/database.py", line 109, in connect
    self._conn: "MariadbConnection" | "PostgresConnection" = self.get_connection()
  File "/home/magic/frappe-bench/apps/frappe/frappe/database/mariadb/database.py", line 107, in get_connection
    conn = self._get_connection()
  File "/home/magic/frappe-bench/apps/frappe/frappe/database/mariadb/database.py", line 113, in _get_connection
    return self.create_connection()
  File "/home/magic/frappe-bench/apps/frappe/frappe/database/mariadb/database.py", line 116, in create_connection
    return pymysql.connect(**self.get_connection_settings())
  File "/home/magic/frappe-bench/env/lib/python3.10/site-packages/pymysql/connections.py", line 361, in __init__
    self.connect()
  File "/home/magic/frappe-bench/env/lib/python3.10/site-packages/pymysql/connections.py", line 669, in connect
    self._request_authentication()
  File "/home/magic/frappe-bench/env/lib/python3.10/site-packages/pymysql/connections.py", line 957, in _request_authentication
    auth_packet = self._read_packet()
  File "/home/magic/frappe-bench/env/lib/python3.10/site-packages/pymysql/connections.py", line 775, in _read_packet
    packet.raise_for_error()
  File "/home/magic/frappe-bench/env/lib/python3.10/site-packages/pymysql/protocol.py", line 219, in raise_for_error
    err.raise_mysql_exception(self._data)
  File "/home/magic/frappe-bench/env/lib/python3.10/site-packages/pymysql/err.py", line 150, in raise_mysql_exception
    raise errorclass(errno, errval)
pymysql.err.OperationalError: (1049, "Unknown database '_7c4e36808ec69197'")
2024-09-22 13:44:26,898 ERROR scheduler Exception in Enqueue Events for Site maigctable
Traceback (most recent call last):
  File "/home/magic/frappe-bench/apps/frappe/frappe/utils/scheduler.py", line 75, in enqueue_events_for_site
    if is_scheduler_inactive():
  File "/home/magic/frappe-bench/apps/frappe/frappe/utils/scheduler.py", line 117, in is_scheduler_inactive
    if is_scheduler_disabled(verbose=verbose):
  File "/home/magic/frappe-bench/apps/frappe/frappe/utils/scheduler.py", line 130, in is_scheduler_disabled
    frappe.db.get_single_value("System Settings", "enable_scheduler")
  File "/home/magic/frappe-bench/apps/frappe/frappe/database/database.py", line 834, in get_single_value
    ).run()
  File "/home/magic/frappe-bench/apps/frappe/frappe/query_builder/utils.py", line 87, in execute_query
    result = frappe.db.sql(query, params, *args, **kwargs)  # nosemgrep
  File "/home/magic/frappe-bench/apps/frappe/frappe/database/database.py", line 204, in sql
    self.connect()
  File "/home/magic/frappe-bench/apps/frappe/frappe/database/database.py", line 109, in connect
    self._conn: "MariadbConnection" | "PostgresConnection" = self.get_connection()
  File "/home/magic/frappe-bench/apps/frappe/frappe/database/mariadb/database.py", line 107, in get_connection
    conn = self._get_connection()
  File "/home/magic/frappe-bench/apps/frappe/frappe/database/mariadb/database.py", line 113, in _get_connection
    return self.create_connection()
  File "/home/magic/frappe-bench/apps/frappe/frappe/database/mariadb/database.py", line 116, in create_connection
    return pymysql.connect(**self.get_connection_settings())
  File "/home/magic/frappe-bench/env/lib/python3.10/site-packages/pymysql/connections.py", line 361, in __init__
    self.connect()
  File "/home/magic/frappe-bench/env/lib/python3.10/site-packages/pymysql/connections.py", line 669, in connect
    self._request_authentication()
  File "/home/magic/frappe-bench/env/lib/python3.10/site-packages/pymysql/connections.py", line 957, in _request_authentication
    auth_packet = self._read_packet()
  File "/home/magic/frappe-bench/env/lib/python3.10/site-packages/pymysql/connections.py", line 775, in _read_packet
    packet.raise_for_error()
  File "/home/magic/frappe-bench/env/lib/python3.10/site-packages/pymysql/protocol.py", line 219, in raise_for_error
    err.raise_mysql_exception(self._data)
  File "/home/magic/frappe-bench/env/lib/python3.10/site-packages/pymysql/err.py", line 150, in raise_mysql_exception
    raise errorclass(errno, errval)
pymysql.err.OperationalError: (1049, "Unknown database '_7c4e36808ec69197'")
2024-09-22 13:45:26,994 ERROR scheduler Exception in Enqueue Events for Site maigctable
Traceback (most recent call last):
  File "/home/magic/frappe-bench/apps/frappe/frappe/utils/scheduler.py", line 75, in enqueue_events_for_site
    if is_scheduler_inactive():
  File "/home/magic/frappe-bench/apps/frappe/frappe/utils/scheduler.py", line 117, in is_scheduler_inactive
    if is_scheduler_disabled(verbose=verbose):
  File "/home/magic/frappe-bench/apps/frappe/frappe/utils/scheduler.py", line 130, in is_scheduler_disabled
    frappe.db.get_single_value("System Settings", "enable_scheduler")
  File "/home/magic/frappe-bench/apps/frappe/frappe/database/database.py", line 834, in get_single_value
    ).run()
  File "/home/magic/frappe-bench/apps/frappe/frappe/query_builder/utils.py", line 87, in execute_query
    result = frappe.db.sql(query, params, *args, **kwargs)  # nosemgrep
  File "/home/magic/frappe-bench/apps/frappe/frappe/database/database.py", line 204, in sql
    self.connect()
  File "/home/magic/frappe-bench/apps/frappe/frappe/database/database.py", line 109, in connect
    self._conn: "MariadbConnection" | "PostgresConnection" = self.get_connection()
  File "/home/magic/frappe-bench/apps/frappe/frappe/database/mariadb/database.py", line 107, in get_connection
    conn = self._get_connection()
  File "/home/magic/frappe-bench/apps/frappe/frappe/database/mariadb/database.py", line 113, in _get_connection
    return self.create_connection()
  File "/home/magic/frappe-bench/apps/frappe/frappe/database/mariadb/database.py", line 116, in create_connection
    return pymysql.connect(**self.get_connection_settings())
  File "/home/magic/frappe-bench/env/lib/python3.10/site-packages/pymysql/connections.py", line 361, in __init__
    self.connect()
  File "/home/magic/frappe-bench/env/lib/python3.10/site-packages/pymysql/connections.py", line 669, in connect
    self._request_authentication()
  File "/home/magic/frappe-bench/env/lib/python3.10/site-packages/pymysql/connections.py", line 957, in _request_authentication
    auth_packet = self._read_packet()
  File "/home/magic/frappe-bench/env/lib/python3.10/site-packages/pymysql/connections.py", line 775, in _read_packet
    packet.raise_for_error()
  File "/home/magic/frappe-bench/env/lib/python3.10/site-packages/pymysql/protocol.py", line 219, in raise_for_error
    err.raise_mysql_exception(self._data)
  File "/home/magic/frappe-bench/env/lib/python3.10/site-packages/pymysql/err.py", line 150, in raise_mysql_exception
    raise errorclass(errno, errval)
pymysql.err.OperationalError: (1049, "Unknown database '_7c4e36808ec69197'")
2024-09-22 13:46:27,118 ERROR scheduler Exception in Enqueue Events for Site maigctable
Traceback (most recent call last):
  File "/home/magic/frappe-bench/apps/frappe/frappe/utils/scheduler.py", line 75, in enqueue_events_for_site
    if is_scheduler_inactive():
  File "/home/magic/frappe-bench/apps/frappe/frappe/utils/scheduler.py", line 117, in is_scheduler_inactive
    if is_scheduler_disabled(verbose=verbose):
  File "/home/magic/frappe-bench/apps/frappe/frappe/utils/scheduler.py", line 130, in is_scheduler_disabled
    frappe.db.get_single_value("System Settings", "enable_scheduler")
  File "/home/magic/frappe-bench/apps/frappe/frappe/database/database.py", line 834, in get_single_value
    ).run()
  File "/home/magic/frappe-bench/apps/frappe/frappe/query_builder/utils.py", line 87, in execute_query
    result = frappe.db.sql(query, params, *args, **kwargs)  # nosemgrep
  File "/home/magic/frappe-bench/apps/frappe/frappe/database/database.py", line 204, in sql
    self.connect()
  File "/home/magic/frappe-bench/apps/frappe/frappe/database/database.py", line 109, in connect
    self._conn: "MariadbConnection" | "PostgresConnection" = self.get_connection()
  File "/home/magic/frappe-bench/apps/frappe/frappe/database/mariadb/database.py", line 107, in get_connection
    conn = self._get_connection()
  File "/home/magic/frappe-bench/apps/frappe/frappe/database/mariadb/database.py", line 113, in _get_connection
    return self.create_connection()
  File "/home/magic/frappe-bench/apps/frappe/frappe/database/mariadb/database.py", line 116, in create_connection
    return pymysql.connect(**self.get_connection_settings())
  File "/home/magic/frappe-bench/env/lib/python3.10/site-packages/pymysql/connections.py", line 361, in __init__
    self.connect()
  File "/home/magic/frappe-bench/env/lib/python3.10/site-packages/pymysql/connections.py", line 669, in connect
    self._request_authentication()
  File "/home/magic/frappe-bench/env/lib/python3.10/site-packages/pymysql/connections.py", line 957, in _request_authentication
    auth_packet = self._read_packet()
  File "/home/magic/frappe-bench/env/lib/python3.10/site-packages/pymysql/connections.py", line 775, in _read_packet
    packet.raise_for_error()
  File "/home/magic/frappe-bench/env/lib/python3.10/site-packages/pymysql/protocol.py", line 219, in raise_for_error
    err.raise_mysql_exception(self._data)
  File "/home/magic/frappe-bench/env/lib/python3.10/site-packages/pymysql/err.py", line 150, in raise_mysql_exception
    raise errorclass(errno, errval)
pymysql.err.OperationalError: (1049, "Unknown database '_7c4e36808ec69197'")
2024-09-22 13:47:27,280 ERROR scheduler Exception in Enqueue Events for Site maigctable
Traceback (most recent call last):
  File "/home/magic/frappe-bench/apps/frappe/frappe/utils/scheduler.py", line 75, in enqueue_events_for_site
    if is_scheduler_inactive():
  File "/home/magic/frappe-bench/apps/frappe/frappe/utils/scheduler.py", line 117, in is_scheduler_inactive
    if is_scheduler_disabled(verbose=verbose):
  File "/home/magic/frappe-bench/apps/frappe/frappe/utils/scheduler.py", line 130, in is_scheduler_disabled
    frappe.db.get_single_value("System Settings", "enable_scheduler")
  File "/home/magic/frappe-bench/apps/frappe/frappe/database/database.py", line 834, in get_single_value
    ).run()
  File "/home/magic/frappe-bench/apps/frappe/frappe/query_builder/utils.py", line 87, in execute_query
    result = frappe.db.sql(query, params, *args, **kwargs)  # nosemgrep
  File "/home/magic/frappe-bench/apps/frappe/frappe/database/database.py", line 204, in sql
    self.connect()
  File "/home/magic/frappe-bench/apps/frappe/frappe/database/database.py", line 109, in connect
    self._conn: "MariadbConnection" | "PostgresConnection" = self.get_connection()
  File "/home/magic/frappe-bench/apps/frappe/frappe/database/mariadb/database.py", line 107, in get_connection
    conn = self._get_connection()
  File "/home/magic/frappe-bench/apps/frappe/frappe/database/mariadb/database.py", line 113, in _get_connection
    return self.create_connection()
  File "/home/magic/frappe-bench/apps/frappe/frappe/database/mariadb/database.py", line 116, in create_connection
    return pymysql.connect(**self.get_connection_settings())
  File "/home/magic/frappe-bench/env/lib/python3.10/site-packages/pymysql/connections.py", line 361, in __init__
    self.connect()
  File "/home/magic/frappe-bench/env/lib/python3.10/site-packages/pymysql/connections.py", line 669, in connect
    self._request_authentication()
  File "/home/magic/frappe-bench/env/lib/python3.10/site-packages/pymysql/connections.py", line 957, in _request_authentication
    auth_packet = self._read_packet()
  File "/home/magic/frappe-bench/env/lib/python3.10/site-packages/pymysql/connections.py", line 775, in _read_packet
    packet.raise_for_error()
  File "/home/magic/frappe-bench/env/lib/python3.10/site-packages/pymysql/protocol.py", line 219, in raise_for_error
    err.raise_mysql_exception(self._data)
  File "/home/magic/frappe-bench/env/lib/python3.10/site-packages/pymysql/err.py", line 150, in raise_mysql_exception
    raise errorclass(errno, errval)
pymysql.err.OperationalError: (1049, "Unknown database '_7c4e36808ec69197'")
2024-09-22 13:48:27,432 ERROR scheduler Exception in Enqueue Events for Site maigctable
Traceback (most recent call last):
  File "/home/magic/frappe-bench/apps/frappe/frappe/utils/scheduler.py", line 75, in enqueue_events_for_site
    if is_scheduler_inactive():
  File "/home/magic/frappe-bench/apps/frappe/frappe/utils/scheduler.py", line 117, in is_scheduler_inactive
    if is_scheduler_disabled(verbose=verbose):
  File "/home/magic/frappe-bench/apps/frappe/frappe/utils/scheduler.py", line 130, in is_scheduler_disabled
    frappe.db.get_single_value("System Settings", "enable_scheduler")
  File "/home/magic/frappe-bench/apps/frappe/frappe/database/database.py", line 834, in get_single_value
    ).run()
  File "/home/magic/frappe-bench/apps/frappe/frappe/query_builder/utils.py", line 87, in execute_query
    result = frappe.db.sql(query, params, *args, **kwargs)  # nosemgrep
  File "/home/magic/frappe-bench/apps/frappe/frappe/database/database.py", line 204, in sql
    self.connect()
  File "/home/magic/frappe-bench/apps/frappe/frappe/database/database.py", line 109, in connect
    self._conn: "MariadbConnection" | "PostgresConnection" = self.get_connection()
  File "/home/magic/frappe-bench/apps/frappe/frappe/database/mariadb/database.py", line 107, in get_connection
    conn = self._get_connection()
  File "/home/magic/frappe-bench/apps/frappe/frappe/database/mariadb/database.py", line 113, in _get_connection
    return self.create_connection()
  File "/home/magic/frappe-bench/apps/frappe/frappe/database/mariadb/database.py", line 116, in create_connection
    return pymysql.connect(**self.get_connection_settings())
  File "/home/magic/frappe-bench/env/lib/python3.10/site-packages/pymysql/connections.py", line 361, in __init__
    self.connect()
  File "/home/magic/frappe-bench/env/lib/python3.10/site-packages/pymysql/connections.py", line 669, in connect
    self._request_authentication()
  File "/home/magic/frappe-bench/env/lib/python3.10/site-packages/pymysql/connections.py", line 957, in _request_authentication
    auth_packet = self._read_packet()
  File "/home/magic/frappe-bench/env/lib/python3.10/site-packages/pymysql/connections.py", line 775, in _read_packet
    packet.raise_for_error()
  File "/home/magic/frappe-bench/env/lib/python3.10/site-packages/pymysql/protocol.py", line 219, in raise_for_error
    err.raise_mysql_exception(self._data)
  File "/home/magic/frappe-bench/env/lib/python3.10/site-packages/pymysql/err.py", line 150, in raise_mysql_exception
    raise errorclass(errno, errval)
pymysql.err.OperationalError: (1049, "Unknown database '_7c4e36808ec69197'")
2024-09-22 13:49:27,593 ERROR scheduler Exception in Enqueue Events for Site maigctable
Traceback (most recent call last):
  File "/home/magic/frappe-bench/apps/frappe/frappe/utils/scheduler.py", line 75, in enqueue_events_for_site
    if is_scheduler_inactive():
  File "/home/magic/frappe-bench/apps/frappe/frappe/utils/scheduler.py", line 117, in is_scheduler_inactive
    if is_scheduler_disabled(verbose=verbose):
  File "/home/magic/frappe-bench/apps/frappe/frappe/utils/scheduler.py", line 130, in is_scheduler_disabled
    frappe.db.get_single_value("System Settings", "enable_scheduler")
  File "/home/magic/frappe-bench/apps/frappe/frappe/database/database.py", line 834, in get_single_value
    ).run()
  File "/home/magic/frappe-bench/apps/frappe/frappe/query_builder/utils.py", line 87, in execute_query
    result = frappe.db.sql(query, params, *args, **kwargs)  # nosemgrep
  File "/home/magic/frappe-bench/apps/frappe/frappe/database/database.py", line 204, in sql
    self.connect()
  File "/home/magic/frappe-bench/apps/frappe/frappe/database/database.py", line 109, in connect
    self._conn: "MariadbConnection" | "PostgresConnection" = self.get_connection()
  File "/home/magic/frappe-bench/apps/frappe/frappe/database/mariadb/database.py", line 107, in get_connection
    conn = self._get_connection()
  File "/home/magic/frappe-bench/apps/frappe/frappe/database/mariadb/database.py", line 113, in _get_connection
    return self.create_connection()
  File "/home/magic/frappe-bench/apps/frappe/frappe/database/mariadb/database.py", line 116, in create_connection
    return pymysql.connect(**self.get_connection_settings())
  File "/home/magic/frappe-bench/env/lib/python3.10/site-packages/pymysql/connections.py", line 361, in __init__
    self.connect()
  File "/home/magic/frappe-bench/env/lib/python3.10/site-packages/pymysql/connections.py", line 669, in connect
    self._request_authentication()
  File "/home/magic/frappe-bench/env/lib/python3.10/site-packages/pymysql/connections.py", line 957, in _request_authentication
    auth_packet = self._read_packet()
  File "/home/magic/frappe-bench/env/lib/python3.10/site-packages/pymysql/connections.py", line 775, in _read_packet
    packet.raise_for_error()
  File "/home/magic/frappe-bench/env/lib/python3.10/site-packages/pymysql/protocol.py", line 219, in raise_for_error
    err.raise_mysql_exception(self._data)
  File "/home/magic/frappe-bench/env/lib/python3.10/site-packages/pymysql/err.py", line 150, in raise_mysql_exception
    raise errorclass(errno, errval)
pymysql.err.OperationalError: (1049, "Unknown database '_7c4e36808ec69197'")
2024-09-22 13:50:27,760 ERROR scheduler Exception in Enqueue Events for Site maigctable
Traceback (most recent call last):
  File "/home/magic/frappe-bench/apps/frappe/frappe/utils/scheduler.py", line 75, in enqueue_events_for_site
    if is_scheduler_inactive():
  File "/home/magic/frappe-bench/apps/frappe/frappe/utils/scheduler.py", line 117, in is_scheduler_inactive
    if is_scheduler_disabled(verbose=verbose):
  File "/home/magic/frappe-bench/apps/frappe/frappe/utils/scheduler.py", line 130, in is_scheduler_disabled
    frappe.db.get_single_value("System Settings", "enable_scheduler")
  File "/home/magic/frappe-bench/apps/frappe/frappe/database/database.py", line 834, in get_single_value
    ).run()
  File "/home/magic/frappe-bench/apps/frappe/frappe/query_builder/utils.py", line 87, in execute_query
    result = frappe.db.sql(query, params, *args, **kwargs)  # nosemgrep
  File "/home/magic/frappe-bench/apps/frappe/frappe/database/database.py", line 204, in sql
    self.connect()
  File "/home/magic/frappe-bench/apps/frappe/frappe/database/database.py", line 109, in connect
    self._conn: "MariadbConnection" | "PostgresConnection" = self.get_connection()
  File "/home/magic/frappe-bench/apps/frappe/frappe/database/mariadb/database.py", line 107, in get_connection
    conn = self._get_connection()
  File "/home/magic/frappe-bench/apps/frappe/frappe/database/mariadb/database.py", line 113, in _get_connection
    return self.create_connection()
  File "/home/magic/frappe-bench/apps/frappe/frappe/database/mariadb/database.py", line 116, in create_connection
    return pymysql.connect(**self.get_connection_settings())
  File "/home/magic/frappe-bench/env/lib/python3.10/site-packages/pymysql/connections.py", line 361, in __init__
    self.connect()
  File "/home/magic/frappe-bench/env/lib/python3.10/site-packages/pymysql/connections.py", line 669, in connect
    self._request_authentication()
  File "/home/magic/frappe-bench/env/lib/python3.10/site-packages/pymysql/connections.py", line 957, in _request_authentication
    auth_packet = self._read_packet()
  File "/home/magic/frappe-bench/env/lib/python3.10/site-packages/pymysql/connections.py", line 775, in _read_packet
    packet.raise_for_error()
  File "/home/magic/frappe-bench/env/lib/python3.10/site-packages/pymysql/protocol.py", line 219, in raise_for_error
    err.raise_mysql_exception(self._data)
  File "/home/magic/frappe-bench/env/lib/python3.10/site-packages/pymysql/err.py", line 150, in raise_mysql_exception
    raise errorclass(errno, errval)
pymysql.err.OperationalError: (1049, "Unknown database '_7c4e36808ec69197'")
2024-09-22 13:51:27,895 ERROR scheduler Exception in Enqueue Events for Site maigctable
Traceback (most recent call last):
  File "/home/magic/frappe-bench/apps/frappe/frappe/utils/scheduler.py", line 75, in enqueue_events_for_site
    if is_scheduler_inactive():
  File "/home/magic/frappe-bench/apps/frappe/frappe/utils/scheduler.py", line 117, in is_scheduler_inactive
    if is_scheduler_disabled(verbose=verbose):
  File "/home/magic/frappe-bench/apps/frappe/frappe/utils/scheduler.py", line 130, in is_scheduler_disabled
    frappe.db.get_single_value("System Settings", "enable_scheduler")
  File "/home/magic/frappe-bench/apps/frappe/frappe/database/database.py", line 834, in get_single_value
    ).run()
  File "/home/magic/frappe-bench/apps/frappe/frappe/query_builder/utils.py", line 87, in execute_query
    result = frappe.db.sql(query, params, *args, **kwargs)  # nosemgrep
  File "/home/magic/frappe-bench/apps/frappe/frappe/database/database.py", line 204, in sql
    self.connect()
  File "/home/magic/frappe-bench/apps/frappe/frappe/database/database.py", line 109, in connect
    self._conn: "MariadbConnection" | "PostgresConnection" = self.get_connection()
  File "/home/magic/frappe-bench/apps/frappe/frappe/database/mariadb/database.py", line 107, in get_connection
    conn = self._get_connection()
  File "/home/magic/frappe-bench/apps/frappe/frappe/database/mariadb/database.py", line 113, in _get_connection
    return self.create_connection()
  File "/home/magic/frappe-bench/apps/frappe/frappe/database/mariadb/database.py", line 116, in create_connection
    return pymysql.connect(**self.get_connection_settings())
  File "/home/magic/frappe-bench/env/lib/python3.10/site-packages/pymysql/connections.py", line 361, in __init__
    self.connect()
  File "/home/magic/frappe-bench/env/lib/python3.10/site-packages/pymysql/connections.py", line 669, in connect
    self._request_authentication()
  File "/home/magic/frappe-bench/env/lib/python3.10/site-packages/pymysql/connections.py", line 957, in _request_authentication
    auth_packet = self._read_packet()
  File "/home/magic/frappe-bench/env/lib/python3.10/site-packages/pymysql/connections.py", line 775, in _read_packet
    packet.raise_for_error()
  File "/home/magic/frappe-bench/env/lib/python3.10/site-packages/pymysql/protocol.py", line 219, in raise_for_error
    err.raise_mysql_exception(self._data)
  File "/home/magic/frappe-bench/env/lib/python3.10/site-packages/pymysql/err.py", line 150, in raise_mysql_exception
    raise errorclass(errno, errval)
pymysql.err.OperationalError: (1049, "Unknown database '_7c4e36808ec69197'")
2024-09-22 13:52:28,036 ERROR scheduler Exception in Enqueue Events for Site maigctable
Traceback (most recent call last):
  File "/home/magic/frappe-bench/apps/frappe/frappe/utils/scheduler.py", line 75, in enqueue_events_for_site
    if is_scheduler_inactive():
  File "/home/magic/frappe-bench/apps/frappe/frappe/utils/scheduler.py", line 117, in is_scheduler_inactive
    if is_scheduler_disabled(verbose=verbose):
  File "/home/magic/frappe-bench/apps/frappe/frappe/utils/scheduler.py", line 130, in is_scheduler_disabled
    frappe.db.get_single_value("System Settings", "enable_scheduler")
  File "/home/magic/frappe-bench/apps/frappe/frappe/database/database.py", line 834, in get_single_value
    ).run()
  File "/home/magic/frappe-bench/apps/frappe/frappe/query_builder/utils.py", line 87, in execute_query
    result = frappe.db.sql(query, params, *args, **kwargs)  # nosemgrep
  File "/home/magic/frappe-bench/apps/frappe/frappe/database/database.py", line 204, in sql
    self.connect()
  File "/home/magic/frappe-bench/apps/frappe/frappe/database/database.py", line 109, in connect
    self._conn: "MariadbConnection" | "PostgresConnection" = self.get_connection()
  File "/home/magic/frappe-bench/apps/frappe/frappe/database/mariadb/database.py", line 107, in get_connection
    conn = self._get_connection()
  File "/home/magic/frappe-bench/apps/frappe/frappe/database/mariadb/database.py", line 113, in _get_connection
    return self.create_connection()
  File "/home/magic/frappe-bench/apps/frappe/frappe/database/mariadb/database.py", line 116, in create_connection
    return pymysql.connect(**self.get_connection_settings())
  File "/home/magic/frappe-bench/env/lib/python3.10/site-packages/pymysql/connections.py", line 361, in __init__
    self.connect()
  File "/home/magic/frappe-bench/env/lib/python3.10/site-packages/pymysql/connections.py", line 669, in connect
    self._request_authentication()
  File "/home/magic/frappe-bench/env/lib/python3.10/site-packages/pymysql/connections.py", line 957, in _request_authentication
    auth_packet = self._read_packet()
  File "/home/magic/frappe-bench/env/lib/python3.10/site-packages/pymysql/connections.py", line 775, in _read_packet
    packet.raise_for_error()
  File "/home/magic/frappe-bench/env/lib/python3.10/site-packages/pymysql/protocol.py", line 219, in raise_for_error
    err.raise_mysql_exception(self._data)
  File "/home/magic/frappe-bench/env/lib/python3.10/site-packages/pymysql/err.py", line 150, in raise_mysql_exception
    raise errorclass(errno, errval)
pymysql.err.OperationalError: (1049, "Unknown database '_7c4e36808ec69197'")
2024-09-22 13:53:28,052 ERROR scheduler Exception in Enqueue Events for Site maigctable
Traceback (most recent call last):
  File "/home/magic/frappe-bench/apps/frappe/frappe/utils/scheduler.py", line 75, in enqueue_events_for_site
    if is_scheduler_inactive():
  File "/home/magic/frappe-bench/apps/frappe/frappe/utils/scheduler.py", line 117, in is_scheduler_inactive
    if is_scheduler_disabled(verbose=verbose):
  File "/home/magic/frappe-bench/apps/frappe/frappe/utils/scheduler.py", line 130, in is_scheduler_disabled
    frappe.db.get_single_value("System Settings", "enable_scheduler")
  File "/home/magic/frappe-bench/apps/frappe/frappe/database/database.py", line 834, in get_single_value
    ).run()
  File "/home/magic/frappe-bench/apps/frappe/frappe/query_builder/utils.py", line 87, in execute_query
    result = frappe.db.sql(query, params, *args, **kwargs)  # nosemgrep
  File "/home/magic/frappe-bench/apps/frappe/frappe/database/database.py", line 204, in sql
    self.connect()
  File "/home/magic/frappe-bench/apps/frappe/frappe/database/database.py", line 109, in connect
    self._conn: "MariadbConnection" | "PostgresConnection" = self.get_connection()
  File "/home/magic/frappe-bench/apps/frappe/frappe/database/mariadb/database.py", line 107, in get_connection
    conn = self._get_connection()
  File "/home/magic/frappe-bench/apps/frappe/frappe/database/mariadb/database.py", line 113, in _get_connection
    return self.create_connection()
  File "/home/magic/frappe-bench/apps/frappe/frappe/database/mariadb/database.py", line 116, in create_connection
    return pymysql.connect(**self.get_connection_settings())
  File "/home/magic/frappe-bench/env/lib/python3.10/site-packages/pymysql/connections.py", line 361, in __init__
    self.connect()
  File "/home/magic/frappe-bench/env/lib/python3.10/site-packages/pymysql/connections.py", line 669, in connect
    self._request_authentication()
  File "/home/magic/frappe-bench/env/lib/python3.10/site-packages/pymysql/connections.py", line 957, in _request_authentication
    auth_packet = self._read_packet()
  File "/home/magic/frappe-bench/env/lib/python3.10/site-packages/pymysql/connections.py", line 775, in _read_packet
    packet.raise_for_error()
  File "/home/magic/frappe-bench/env/lib/python3.10/site-packages/pymysql/protocol.py", line 219, in raise_for_error
    err.raise_mysql_exception(self._data)
  File "/home/magic/frappe-bench/env/lib/python3.10/site-packages/pymysql/err.py", line 150, in raise_mysql_exception
    raise errorclass(errno, errval)
pymysql.err.OperationalError: (1049, "Unknown database '_7c4e36808ec69197'")
2024-09-22 13:54:28,155 ERROR scheduler Exception in Enqueue Events for Site maigctable
Traceback (most recent call last):
  File "/home/magic/frappe-bench/apps/frappe/frappe/utils/scheduler.py", line 75, in enqueue_events_for_site
    if is_scheduler_inactive():
  File "/home/magic/frappe-bench/apps/frappe/frappe/utils/scheduler.py", line 117, in is_scheduler_inactive
    if is_scheduler_disabled(verbose=verbose):
  File "/home/magic/frappe-bench/apps/frappe/frappe/utils/scheduler.py", line 130, in is_scheduler_disabled
    frappe.db.get_single_value("System Settings", "enable_scheduler")
  File "/home/magic/frappe-bench/apps/frappe/frappe/database/database.py", line 834, in get_single_value
    ).run()
  File "/home/magic/frappe-bench/apps/frappe/frappe/query_builder/utils.py", line 87, in execute_query
    result = frappe.db.sql(query, params, *args, **kwargs)  # nosemgrep
  File "/home/magic/frappe-bench/apps/frappe/frappe/database/database.py", line 204, in sql
    self.connect()
  File "/home/magic/frappe-bench/apps/frappe/frappe/database/database.py", line 109, in connect
    self._conn: "MariadbConnection" | "PostgresConnection" = self.get_connection()
  File "/home/magic/frappe-bench/apps/frappe/frappe/database/mariadb/database.py", line 107, in get_connection
    conn = self._get_connection()
  File "/home/magic/frappe-bench/apps/frappe/frappe/database/mariadb/database.py", line 113, in _get_connection
    return self.create_connection()
  File "/home/magic/frappe-bench/apps/frappe/frappe/database/mariadb/database.py", line 116, in create_connection
    return pymysql.connect(**self.get_connection_settings())
  File "/home/magic/frappe-bench/env/lib/python3.10/site-packages/pymysql/connections.py", line 361, in __init__
    self.connect()
  File "/home/magic/frappe-bench/env/lib/python3.10/site-packages/pymysql/connections.py", line 669, in connect
    self._request_authentication()
  File "/home/magic/frappe-bench/env/lib/python3.10/site-packages/pymysql/connections.py", line 957, in _request_authentication
    auth_packet = self._read_packet()
  File "/home/magic/frappe-bench/env/lib/python3.10/site-packages/pymysql/connections.py", line 775, in _read_packet
    packet.raise_for_error()
  File "/home/magic/frappe-bench/env/lib/python3.10/site-packages/pymysql/protocol.py", line 219, in raise_for_error
    err.raise_mysql_exception(self._data)
  File "/home/magic/frappe-bench/env/lib/python3.10/site-packages/pymysql/err.py", line 150, in raise_mysql_exception
    raise errorclass(errno, errval)
pymysql.err.OperationalError: (1049, "Unknown database '_7c4e36808ec69197'")
2024-09-22 13:55:28,221 ERROR scheduler Exception in Enqueue Events for Site maigctable
Traceback (most recent call last):
  File "/home/magic/frappe-bench/apps/frappe/frappe/utils/scheduler.py", line 75, in enqueue_events_for_site
    if is_scheduler_inactive():
  File "/home/magic/frappe-bench/apps/frappe/frappe/utils/scheduler.py", line 117, in is_scheduler_inactive
    if is_scheduler_disabled(verbose=verbose):
  File "/home/magic/frappe-bench/apps/frappe/frappe/utils/scheduler.py", line 130, in is_scheduler_disabled
    frappe.db.get_single_value("System Settings", "enable_scheduler")
  File "/home/magic/frappe-bench/apps/frappe/frappe/database/database.py", line 834, in get_single_value
    ).run()
  File "/home/magic/frappe-bench/apps/frappe/frappe/query_builder/utils.py", line 87, in execute_query
    result = frappe.db.sql(query, params, *args, **kwargs)  # nosemgrep
  File "/home/magic/frappe-bench/apps/frappe/frappe/database/database.py", line 204, in sql
    self.connect()
  File "/home/magic/frappe-bench/apps/frappe/frappe/database/database.py", line 109, in connect
    self._conn: "MariadbConnection" | "PostgresConnection" = self.get_connection()
  File "/home/magic/frappe-bench/apps/frappe/frappe/database/mariadb/database.py", line 107, in get_connection
    conn = self._get_connection()
  File "/home/magic/frappe-bench/apps/frappe/frappe/database/mariadb/database.py", line 113, in _get_connection
    return self.create_connection()
  File "/home/magic/frappe-bench/apps/frappe/frappe/database/mariadb/database.py", line 116, in create_connection
    return pymysql.connect(**self.get_connection_settings())
  File "/home/magic/frappe-bench/env/lib/python3.10/site-packages/pymysql/connections.py", line 361, in __init__
    self.connect()
  File "/home/magic/frappe-bench/env/lib/python3.10/site-packages/pymysql/connections.py", line 669, in connect
    self._request_authentication()
  File "/home/magic/frappe-bench/env/lib/python3.10/site-packages/pymysql/connections.py", line 957, in _request_authentication
    auth_packet = self._read_packet()
  File "/home/magic/frappe-bench/env/lib/python3.10/site-packages/pymysql/connections.py", line 775, in _read_packet
    packet.raise_for_error()
  File "/home/magic/frappe-bench/env/lib/python3.10/site-packages/pymysql/protocol.py", line 219, in raise_for_error
    err.raise_mysql_exception(self._data)
  File "/home/magic/frappe-bench/env/lib/python3.10/site-packages/pymysql/err.py", line 150, in raise_mysql_exception
    raise errorclass(errno, errval)
pymysql.err.OperationalError: (1049, "Unknown database '_7c4e36808ec69197'")
2024-09-22 13:56:28,367 ERROR scheduler Exception in Enqueue Events for Site maigctable
Traceback (most recent call last):
  File "/home/magic/frappe-bench/apps/frappe/frappe/utils/scheduler.py", line 75, in enqueue_events_for_site
    if is_scheduler_inactive():
  File "/home/magic/frappe-bench/apps/frappe/frappe/utils/scheduler.py", line 117, in is_scheduler_inactive
    if is_scheduler_disabled(verbose=verbose):
  File "/home/magic/frappe-bench/apps/frappe/frappe/utils/scheduler.py", line 130, in is_scheduler_disabled
    frappe.db.get_single_value("System Settings", "enable_scheduler")
  File "/home/magic/frappe-bench/apps/frappe/frappe/database/database.py", line 834, in get_single_value
    ).run()
  File "/home/magic/frappe-bench/apps/frappe/frappe/query_builder/utils.py", line 87, in execute_query
    result = frappe.db.sql(query, params, *args, **kwargs)  # nosemgrep
  File "/home/magic/frappe-bench/apps/frappe/frappe/database/database.py", line 204, in sql
    self.connect()
  File "/home/magic/frappe-bench/apps/frappe/frappe/database/database.py", line 109, in connect
    self._conn: "MariadbConnection" | "PostgresConnection" = self.get_connection()
  File "/home/magic/frappe-bench/apps/frappe/frappe/database/mariadb/database.py", line 107, in get_connection
    conn = self._get_connection()
  File "/home/magic/frappe-bench/apps/frappe/frappe/database/mariadb/database.py", line 113, in _get_connection
    return self.create_connection()
  File "/home/magic/frappe-bench/apps/frappe/frappe/database/mariadb/database.py", line 116, in create_connection
    return pymysql.connect(**self.get_connection_settings())
  File "/home/magic/frappe-bench/env/lib/python3.10/site-packages/pymysql/connections.py", line 361, in __init__
    self.connect()
  File "/home/magic/frappe-bench/env/lib/python3.10/site-packages/pymysql/connections.py", line 669, in connect
    self._request_authentication()
  File "/home/magic/frappe-bench/env/lib/python3.10/site-packages/pymysql/connections.py", line 957, in _request_authentication
    auth_packet = self._read_packet()
  File "/home/magic/frappe-bench/env/lib/python3.10/site-packages/pymysql/connections.py", line 775, in _read_packet
    packet.raise_for_error()
  File "/home/magic/frappe-bench/env/lib/python3.10/site-packages/pymysql/protocol.py", line 219, in raise_for_error
    err.raise_mysql_exception(self._data)
  File "/home/magic/frappe-bench/env/lib/python3.10/site-packages/pymysql/err.py", line 150, in raise_mysql_exception
    raise errorclass(errno, errval)
pymysql.err.OperationalError: (1049, "Unknown database '_7c4e36808ec69197'")
2024-09-22 13:57:28,475 ERROR scheduler Exception in Enqueue Events for Site maigctable
Traceback (most recent call last):
  File "/home/magic/frappe-bench/apps/frappe/frappe/utils/scheduler.py", line 75, in enqueue_events_for_site
    if is_scheduler_inactive():
  File "/home/magic/frappe-bench/apps/frappe/frappe/utils/scheduler.py", line 117, in is_scheduler_inactive
    if is_scheduler_disabled(verbose=verbose):
  File "/home/magic/frappe-bench/apps/frappe/frappe/utils/scheduler.py", line 130, in is_scheduler_disabled
    frappe.db.get_single_value("System Settings", "enable_scheduler")
  File "/home/magic/frappe-bench/apps/frappe/frappe/database/database.py", line 834, in get_single_value
    ).run()
  File "/home/magic/frappe-bench/apps/frappe/frappe/query_builder/utils.py", line 87, in execute_query
    result = frappe.db.sql(query, params, *args, **kwargs)  # nosemgrep
  File "/home/magic/frappe-bench/apps/frappe/frappe/database/database.py", line 204, in sql
    self.connect()
  File "/home/magic/frappe-bench/apps/frappe/frappe/database/database.py", line 109, in connect
    self._conn: "MariadbConnection" | "PostgresConnection" = self.get_connection()
  File "/home/magic/frappe-bench/apps/frappe/frappe/database/mariadb/database.py", line 107, in get_connection
    conn = self._get_connection()
  File "/home/magic/frappe-bench/apps/frappe/frappe/database/mariadb/database.py", line 113, in _get_connection
    return self.create_connection()
  File "/home/magic/frappe-bench/apps/frappe/frappe/database/mariadb/database.py", line 116, in create_connection
    return pymysql.connect(**self.get_connection_settings())
  File "/home/magic/frappe-bench/env/lib/python3.10/site-packages/pymysql/connections.py", line 361, in __init__
    self.connect()
  File "/home/magic/frappe-bench/env/lib/python3.10/site-packages/pymysql/connections.py", line 669, in connect
    self._request_authentication()
  File "/home/magic/frappe-bench/env/lib/python3.10/site-packages/pymysql/connections.py", line 957, in _request_authentication
    auth_packet = self._read_packet()
  File "/home/magic/frappe-bench/env/lib/python3.10/site-packages/pymysql/connections.py", line 775, in _read_packet
    packet.raise_for_error()
  File "/home/magic/frappe-bench/env/lib/python3.10/site-packages/pymysql/protocol.py", line 219, in raise_for_error
    err.raise_mysql_exception(self._data)
  File "/home/magic/frappe-bench/env/lib/python3.10/site-packages/pymysql/err.py", line 150, in raise_mysql_exception
    raise errorclass(errno, errval)
pymysql.err.OperationalError: (1049, "Unknown database '_7c4e36808ec69197'")
2024-09-22 16:16:29,350 ERROR scheduler Exception in Enqueue Events for Site magictable.info
Traceback (most recent call last):
  File "/home/magic/frappe-bench/env/lib/python3.10/site-packages/pymysql/connections.py", line 649, in connect
    sock = socket.create_connection(
  File "/usr/lib/python3.10/socket.py", line 845, in create_connection
    raise err
  File "/usr/lib/python3.10/socket.py", line 833, in create_connection
    sock.connect(sa)
ConnectionRefusedError: [Errno 111] Connection refused

During handling of the above exception, another exception occurred:

Traceback (most recent call last):
  File "/home/magic/frappe-bench/apps/frappe/frappe/utils/scheduler.py", line 75, in enqueue_events_for_site
    if is_scheduler_inactive():
  File "/home/magic/frappe-bench/apps/frappe/frappe/utils/scheduler.py", line 117, in is_scheduler_inactive
    if is_scheduler_disabled(verbose=verbose):
  File "/home/magic/frappe-bench/apps/frappe/frappe/utils/scheduler.py", line 130, in is_scheduler_disabled
    frappe.db.get_single_value("System Settings", "enable_scheduler")
  File "/home/magic/frappe-bench/apps/frappe/frappe/database/database.py", line 834, in get_single_value
    ).run()
  File "/home/magic/frappe-bench/apps/frappe/frappe/query_builder/utils.py", line 87, in execute_query
    result = frappe.db.sql(query, params, *args, **kwargs)  # nosemgrep
  File "/home/magic/frappe-bench/apps/frappe/frappe/database/database.py", line 204, in sql
    self.connect()
  File "/home/magic/frappe-bench/apps/frappe/frappe/database/database.py", line 109, in connect
    self._conn: "MariadbConnection" | "PostgresConnection" = self.get_connection()
  File "/home/magic/frappe-bench/apps/frappe/frappe/database/mariadb/database.py", line 107, in get_connection
    conn = self._get_connection()
  File "/home/magic/frappe-bench/apps/frappe/frappe/database/mariadb/database.py", line 113, in _get_connection
    return self.create_connection()
  File "/home/magic/frappe-bench/apps/frappe/frappe/database/mariadb/database.py", line 116, in create_connection
    return pymysql.connect(**self.get_connection_settings())
  File "/home/magic/frappe-bench/env/lib/python3.10/site-packages/pymysql/connections.py", line 361, in __init__
    self.connect()
  File "/home/magic/frappe-bench/env/lib/python3.10/site-packages/pymysql/connections.py", line 716, in connect
    raise exc
pymysql.err.OperationalError: (2003, "Can't connect to MySQL server on '127.0.0.1' ([Errno 111] Connection refused)")
